Workbook

Sheet READ ME
A1: CHISON / AstraMed, Market Development Target List v19
A2: Dealer model: Taiwan, South Korea, Japan and SINGAPORE. VET tabs per market. Single merged workbook for the DEALER_DIAGNOSTICS folder. v7 issued 3 October 2026.
A4: Prepared for | B4: Casper Tan, Senior Regional Sales Manager — AstraMed Healthcare (CHISON). v1 18 Jul 2026 · v2 7 Aug 2026 · v3 merge 8 Aug 2026.
A5: WHAT v3 IS | B5: v3 is v2's format with every other file in the DEALER_DIAGNOSTICS folder folded in — nothing from the folder is left outside this workbook. Merged sources: (1) CHISON_Market_Development_Target_List_v2.xlsx — the base format and the TW/KR/JP/SG target tabs; (2) CHISON_LinkedIn_Outreach_Log_6Aug2026.xlsx — Session 2 outreach (21 further invites) + the four VET tabs v2 had dropped; (3) CHISON_Taiwan_Dealer_Targets_v2.xlsx — 59 TFDA-registry Taiwan companies + the relevance changelog + the REF/excluded list; (4) SG Contacts Combined.xlsx — 85 named ALPS / public-healthcare procurement contacts + the ALPS tender-cycle notes.
A6: WHAT CHANGED | B6: TAIWAN: the TFDA-registry list is merged into the Taiwan Dealers tab. 54 registry companies were new and are appended after the original 59, tier-ordered, tagged 'TFDA registry' in the Source column. 5 companies appeared on both lists (友信行/Unison, 元利儀器, 科林儀器, 埃默高/Emergo, 華鋒科技/Eastech) — these were NOT duplicated; the registry's verified brand, address and website detail was merged into the existing row. LINKEDIN: the log now carries both sessions — 39 invitations sent, not 18. v2's stale 'NEXT SESSION' block was dropped because the 6 Aug session actually completed it (Ubcare, Medius, Ship Healthcare, Yagami, Mutoh all sent); the live queued/blocked list from 6 Aug replaces it. VET: the four VET tabs are restored from the 6 Aug file and reformatted to v2 style with a Pipeline stage column. SINGAPORE: the 85 named ALPS/public-healthcare contacts sit on their own 'Singapore Contacts' tab — they are people, not target organisations, so the org-level Singapore End-Users tab is unchanged.
A7: PRIORITY AUDIT | B7: v3.0 merged two files whose Tier 1 definitions were incompatible. v2's rule: right segment + scale/service capability + no obvious competing line + a working domain. The TFDA-registry file's rule: 'confirmed ultrasound brand, single/minor line, no deep entrenchment' — which rewards being SMALL and says nothing about capability or reachability. Merging the two tier columns verbatim put six micro-importers and one TPEx-listed competitor (AmCad BioMed) at the top of the Taiwan call list. v3.1 re-scores every registry row against v2's rule, moves AmCad to REF & Excluded, and corrects one Japan row (Green Medical — a used-equipment trader, not a new-brand distributor). 7 changes total, all listed with evidence on the Priority Audit tab, alongside 10 judgements examined and deliberately upheld. Every row on every target tab now carries a 'Priority rationale' cell stating the basis for its tier.
A8: TIER LOGIC | B8: Tier 1 = contact first: right segment + scale/service capability + no obvious competing ultrasound line (or vet-dedicated channel). Tier 2 = second wave: strong channel but existing competing line to qualify, or fit to confirm. Tier 3 = long tail / niche / channel resources (associations, expos, directories, regulators) used to source more leads. REF = competitor or brand subsidiary — awareness only, NOT an outreach target.
A9: YOUR KEY ASK | B9: Dealers with radiology / imaging / OR / endoscopy / cardiology / patient-monitoring experience but NO current ultrasound line are marked 'No known US line' in the 'Carries ultrasound?' column — these carry no brand conflict and are flagged Tier 1/2 accordingly. Directory-sourced dealers have unknown line cards: the first qualification question in outreach is exactly this.
A10: PRODUCT COLUMN | B10: New 'CHISON product focus' column = what to LEAD with per contact, matched to their segment/strength. Portfolio verified on chison.com (Jul 2026) — Carts: SonoPort (new-gen intelligent cart, Apr-26), SonoMax 7 (flagship), XBit 90 (premium), CBit 4/6 (cardio/gyn/radiology mid), QBit 3/5 (value console). Portables: SonoGO (NEW Jul-26, world-first 3-in-1 tablet/laptop/trolley + SonoAI — your freshest demo story), SonoAir 30/70 (lightest laptop), SonoBook 5/9 (workhorse), EBit 50 (value), ECO (budget/B&W), SonoTouch (touch POC). Handheld: SonoEye P3 (ER/ICU/POC) & P5 (phone/pad, high-freq). VET: same platforms with vet presets + micro-convex/linear/rectal probes — chison.com lists SonoEye P3/P5, EBit 50, SonoAir 30/70, SonoBook 5, CBit 4/6, QBit 3/5, XBit 90, SonoMax 7 as vet-suitable. Recommendations are a starting point — confirm configs/probes with HQ before quoting.
A11: SOURCE LEGEND | B11: Verified site = contact taken from the company's own website. Directory = from an industry registry fetched during research (JAHID/Japan, MFDS eMEDI/Korea, TFDA/Taiwan via MedDeviceGuide; SVA registry/SG vets; TPVMA/Taipei vets) — companies are real and registry-verified, but line cards and current status must be qualified. From search = surfaced in web-search results. Knowledge — verify = well-known company from market knowledge; confirm current details before outreach. TFDA registry = company appears in the Taiwan FDA medical-device registration export (104,100 licence records) filtered to ultrasound diagnostic-imaging categories P.1550 / P.1560 / P.1570 / L.2660 / L.2960 / E.2330; manufacturers registering their own product were excluded, and each remaining manufacturer's actual flagship product was web-verified rather than trusted from the category code alone. Addresses on those rows are registered legal addresses, not necessarily the sales office — confirm before outreach.
A12: HONESTY NOTE | B12: No contact details are invented. Where phone/email was not verifiable, the cell says 'via website'. Personal names appearing anywhere are leads to confirm, not confirmed decision-makers. Merge integrity: no row was rewritten, re-scored or invented during this merge. Every cell is either carried verbatim from a source file or is a blank-field default ('Not started' pipeline stage, running row number). The only edited cells are on the 5 deduped Taiwan rows, where registry detail was appended to the existing text.
A13: V3 MERGE (prior) | B13: Your prior 'CHISON_Dealer_List_Asia_v3' has been merged (rows marked 'Prior list v3'). Imported: rows with verifiable websites/phones (e.g., Green Medical & Fair Medical JP, Scanmed/idsMED SG, Soelim/JPI KR, JML/醫影 TW). NOT imported: (a) direct-competitor rows GE/Philips/Siemens/Canon/Mindray/Samsung/Butterfly/Sonoscape etc. — they remain REF-only here; (b) ~35 rows with generic names and every field 'To verify' (e.g., 'Grand Med Technology', 'Medic One Taiwan', 'Finemed', 'Mediflex Japan') — their existence could not be confirmed and they are excluded to keep this an outreach-safe list. Tier-1 website check done: every Tier 1 row now has a working domain (two KR importers with no findable web presence were downgraded to Tier 2).
A14: COVERAGE | B14: Taiwan dealers 112 · Korea dealers 78 (rebuilt in v5) · Japan dealers 68 · SINGAPORE DEALERS 142 rows, 120 dealer targets (rebuilt in v16) · Singapore end-users 61 (now the pull through account map, not the direct sale list) · Singapore named contacts 85 · Singapore private specialist centres 111 and GP clinics 102 (new Singapore_private tab in v7).
A15: TIER 1 COUNT | B15: Taiwan 9 · Korea 22 (was 4 in v4) · Japan 13 · Singapore dealers 12 (new). Korea Tier 1 breaks down as 10 rows with contact details read off the company's own page, 3 verified partially, 6 with a live site but no published contact block, and 3 MFDS registry importers held at Tier 1 on import licence capability alone. The CONTACT CONFIDENCE column on the tab tells you which is which.
... A111: JAPAN ADDITIONAL, WHAT IS NOT VERIFIED | B111: No decision maker verified. Phone, email, website and 法人番号 were not collected for most rows because direct website access was blocked in this session; the rows carry their directory or registry source instead. A 10% random recheck (29 rows) confirmed 7, downgraded 3 welfare equipment firms, partly confirmed 1, removed 2 misfits and could not confirm 16 beyond their listing.

Sheet LinkedIn Outreach Log
A1: LinkedIn Outreach Log — Dealer BD / Sales / Marketing Staff
A2: Sent from Chin Huat Tan's account · Session 1 (19 Jul 2026) + Session 2 (6 Aug 2026) merged · 39 invitations sent · 15 queued/blocked. Neutral framing (no CHISON mention); 1 personalised note used (Sting Wu), rest note-free.
A4: # | B4: Market | C4: Company | D4: Pipeline stage | E4: Person | F4: Title / role | G4: LinkedIn profile | H4: Status | I4: Note?
B5: Session 1 — 19 Jul 2026 · 18 invitations sent (TW 7 · KR 3 · JP 8) · 1 personalised note
A6: 1 | B6: Taiwan | C6: Getz Healthcare TW | D6: Not started | E6: Sting Wu | F6: Managing Director | G6: linkedin.com/in/sting-wu-550bbbb7 | H6: Sent | I6: YES-中文 note
A7: 2 | B7: Taiwan | C7: Getz Healthcare TW | D7: Not started | E7: Neo Shen | F7: Deputy General Manager | G7: linkedin.com/in/neo-shen-154a43ba | H7: Sent | I7: No
A8: 3 | B8: Taiwan | C8: Getz Healthcare TW | D8: Not started | E8: Frank Yan | F8: Product Manager | G8: linkedin.com/in/fuhaoyan | H8: Sent | I8: No
A9: 4 | B9: Taiwan | C9: Getz Healthcare TW | D9: Not started | E9: Lewis Hsu | F9: Product Manager | G9: linkedin.com/in/lewis-hsu | H9: Sent | I9: No
A10: 5 | B10: Taiwan | C10: DKSH 大昌華嘉 | D10: Not started | E10: Mickey Chen | F10: Business Development Manager | G10: linkedin.com/in/mickey-chen-953265124 | H10: Sent | I10: No
A11: 6 | B11: Taiwan | C11: DKSH 大昌華嘉 | D11: Not started | E11: Sam Chien | F11: Senior Manager APAC (BD) | G11: linkedin.com/in/sam-chien-833022b7 | H11: Sent | I11: No
A12: 7 | B12: Taiwan | C12: DKSH Healthcare | D12: Not started | E12: Vinay Badal | F12: VP Commercial Ops, Healthcare (regional) | G12: linkedin.com/in/vinaybadal | H12: Sent | I12: No
A13: 8 | B13: Korea | C13: JW메디칼 | D13: Not started | E13: 유장호 Yoo Jang-ho | F13: 영업관리 (Sales Management) | G13: linkedin.com/in/장호-유-9b85b6209 | H13: Sent | I13: No
A14: 9 | B14: Korea | C14: JW메디칼 | D14: Not started | E14: Dong Kyu (Micky) Lee | F14: 영상영업1팀장 (Imaging Sales Team Ldr) | G14: linkedin.com/in/dong-kyu-micky-lee-56381a138 | H14: Sent | I14: No
A15: 10 | B15: Korea | C15: DK메디칼 | D15: Not started | E15: 신영식 Shin Young-sik | F15: 부장 (Director) | G15: linkedin.com/in/신영식-부장님-435056140 | H15: Sent | I15: No
A16: 11 | B16: Japan | C16: Century Medical | D16: Not started | E16: Junichi Hiramatsu | F16: GM, Medical Device Business Development | G16: linkedin.com/in/junichi-hiramatsu-7013767 | H16: Sent | I16: No
A17: 12 | B17: Japan | C17: Century Medical | D17: Not started | E17: Toshihiko Fujioka | F17: President & CEO | G17: linkedin.com/in/toshihiko-fujioka-4ab55628 | H17: Sent | I17: No
... A23: 18 | B23: Japan | C23: Gadelius Medical | D23: Not started | E23: Minoru Asama | F23: Business Unit Manager | G23: linkedin.com/in/minoru-asama-b730427b | H23: Sent | I23: No
B24: Session 2 — 6 Aug 2026 · 21 invitations sent (KR 7 · JP 14) · all note-free
A25: 19 | B25: Korea | C25: Ubcare 유비케어 | D25: Not started | E25: 노주현 Roh Ju-hyun | F25: 전략기획실장 (Head of Strategic Planning) | G25: linkedin.com/in/주현-노-98b648194 | H25: Sent | I25: No
A26: 20 | B26: Korea | C26: Ubcare 유비케어 | D26: Not started | E26: 한선영 Han Sun-young | F26: 과장 (Manager) | G26: (via Ubcare search rail) | H26: Sent | I26: No
A27: 21 | B27: Korea | C27: Ubcare 유비케어 | D27: Not started | E27: 김준혁 Kim Jun-hyuk | F27: 병원사업본부 (Hospital Business Div.) | G27: linkedin.com/in/준혁-김-854289185 | H27: Sent | I27: No
A28: 22 | B28: Korea | C28: DK Medical Systems | D28: Not started | E28: gyobock (GB) lee | F28: DK Medical Systems Co., Ltd. | G28: linkedin.com/in/gyobock-gb-lee-9654a3b0 | H28: Sent | I28: No
A29: 23 | B29: Korea | C29: DK Medical Systems | D29: Not started | E29: 임현재 Lim Hyun-jae | F29: DK Medical Systems | G29: linkedin.com/in/현재-임-0a03a444 | H29: Sent | I29: No
A30: 24 | B30: Korea | C30: DK Healthcare (DK group) | D30: Not started | E30: SB (SungBum) Cho | F30: Sales & Marketing Lead | G30: linkedin.com/in/sb-sungbum-cho-55160122 | H30: Sent | I30: No
A31: 25 | B31: Korea | C31: DK Healthcare (DK group) | D31: Not started | E31: Junghoon Kim | F31: 부장 (Director) | G31: (via DK search rail) | H31: Sent | I31: No
A32: 26 | B32: Japan | C32: Muranaka Medical ムラナカ | D32: Not started | E32: Shinya Nakamura | F32: Executive Officer, Marketing Supervisor | G32: linkedin.com/in/shinya-nakamura-a5852554 | H32: Sent | I32: No
A33: 27 | B33: Japan | C33: Muranaka Medical ムラナカ | D33: Not started | E33: Ryoko Mine | F33: Marketing & Planning Dept. | G33: linkedin.com/in/ryoko-mine-27b25435 | H33: Sent | I33: No
A34: 28 | B34: Japan | C34: Medius HD メディアスHD | D34: Not started | E34: 浅賀太一 Asaga Taichi | F34: 執行役員 企画統括副本部長 / REPS 社長 | G34: linkedin.com/in/太一-浅賀-71247030a | H34: Sent | I34: No
A35: 29 | B35: Japan | C35: Ship Healthcare シップHD | D35: Not started | E35: 安藤元治 Ando Motoharu | F35: シップヘルスケアホールディングス | G35: linkedin.com/in/元治-安藤-92782341 | H35: Sent | I35: No
A36: 30 | B36: Japan | C36: Ship Healthcare シップHD | D36: Not started | E36: Chisato Ito | F36: 経営企画室 (Corporate Planning Office) | G36: (via Ship HD search rail) | H36: Sent | I36: No
... A45: 39 | B45: Japan | C45: Mutoh ムトウ | D45: Not started | E45: Kouichi Yonaga | F45: 部長 (Department Head, Hokkaido) | G45: (via Mutoh search) | H45: Sent | I45: No
B46: QUEUED / BLOCKED — carried forward from 6 Aug 2026 (supersedes v2's 'NEXT SESSION' block)
B47: Japan | C47: Yagami 八神製作所 | D47: Not started | E47: 高瀬太一, 清家徹 (執行役員), Naoki Wada | F47: Message-only / remaining sales staff | H47: queued
B48: Japan | C48: Ship Healthcare | D48: Not started | E48: yukihiro shiraishi | F48: Message-only, no Connect | H48: queued
B49: Japan | C49: Kishiya キシヤ | D49: Not started | E49: Masahiro Okada (医療機器販売) | F49: Message-only; rest anonymised — phone/email instead | H49: blocked
B50: Japan | C50: Win-Partners ウイン・パートナーズ | D50: Not started | E50: 森嶋尚伯 (部長) | F50: Message-only, no Connect | H50: blocked
B51: Japan | C51: TS Alfresa ティーエスアルフレッサ | D51: Not started | E51: — | F51: All anonymised | H51: blocked
B52: Japan | C52: Kawanishi カワニシ | D52: Not started | E52: — | F52: Field-service + anonymised only | H52: blocked
B53: Japan | C53: Yamashita 山下医科器械 | D53: Not started | E53: — | F53: All anonymised — phone/email instead | H53: blocked
B54: Japan | C54: Intermedical インターメディカル | D54: Not started | E54: — | F54: No LinkedIn presence found | H54: blocked
...

Sheet Outreach Summary
A1: EMAIL OUTREACH SUMMARY BY MARKET: HUMAN DIAGNOSTICS
A2: Live formulas on the Email Outreach Log and the target tabs. Taiwan sends of 6 Oct 2026 are logged; other markets unchanged. Veterinary outreach is tracked in the VET workbook.
A4: Market | B4: Channel | C4: Targets on list | D4: Emails sent | E4: Delivered | F4: Bounced | G4: Replied | H4: No reply yet | I4: Still to email | J4: % of list emailed | K4: Target tab
A5: Singapore | B5: Dealer | C5: =SUMPRODUCT(--ISNUMBER(MATCH('Singapore Dealers'!O5:O146,{1,2,3},0))) | D5: =COUNTIFS('Email Outreach Log'!C:C,A5,'Email Outreach Log'!E:E,B5) | E5: =D5-F5 | F5: =COUNTIFS('Email Outreach Log'!C:C,A5,'Email Outreach Log'!E:E,B5,'Email Outreach Log'!L:L,"Bounced") | G5: =COUNTIFS('Email Outreach Log'!C:C,A5,'Email Outreach Log'!E:E,B5,'Email Outreach Log'!L:L,"Yes") | H5: =COUNTIFS('Email Outreach Log'!C:C,A5,'Email Outreach Log'!E:E,B5,'Email Outreach Log'!L:L,"No")+COUNTIFS('Email Outreach Log'!C:C,A5,'Email Outreach Log'!E:E,B5,'Email Outreach Log'!L:L,"Out of office") | I5: =MAX(C5-D5,0) | J5: =IF(C5=0,0,D5/C5) | K5: Singapore Dealers
A6: Singapore | B6: End user | C6: =COUNTA('Singapore End-Users'!C5:C65) | D6: =COUNTIFS('Email Outreach Log'!C:C,A6,'Email Outreach Log'!E:E,B6) | E6: =D6-F6 | F6: =COUNTIFS('Email Outreach Log'!C:C,A6,'Email Outreach Log'!E:E,B6,'Email Outreach Log'!L:L,"Bounced") | G6: =COUNTIFS('Email Outreach Log'!C:C,A6,'Email Outreach Log'!E:E,B6,'Email Outreach Log'!L:L,"Yes") | H6: =COUNTIFS('Email Outreach Log'!C:C,A6,'Email Outreach Log'!E:E,B6,'Email Outreach Log'!L:L,"No")+COUNTIFS('Email Outreach Log'!C:C,A6,'Email Outreach Log'!E:E,B6,'Email Outreach Log'!L:L,"Out of office") | I6: =MAX(C6-D6,0) | J6: =IF(C6=0,0,D6/C6) | K6: Singapore End-Users
A7: Singapore | B7: Named contact | C7: =COUNTA('Singapore Contacts'!C5:C89) | D7: =COUNTIFS('Email Outreach Log'!C:C,A7,'Email Outreach Log'!E:E,B7) | E7: =D7-F7 | F7: =COUNTIFS('Email Outreach Log'!C:C,A7,'Email Outreach Log'!E:E,B7,'Email Outreach Log'!L:L,"Bounced") | G7: =COUNTIFS('Email Outreach Log'!C:C,A7,'Email Outreach Log'!E:E,B7,'Email Outreach Log'!L:L,"Yes") | H7: =COUNTIFS('Email Outreach Log'!C:C,A7,'Email Outreach Log'!E:E,B7,'Email Outreach Log'!L:L,"No")+COUNTIFS('Email Outreach Log'!C:C,A7,'Email Outreach Log'!E:E,B7,'Email Outreach Log'!L:L,"Out of office") | I7: =MAX(C7-D7,0) | J7: =IF(C7=0,0,D7/C7) | K7: Singapore Contacts
A8: Singapore | B8: Private specialist | C8: =COUNTIF(Singapore_private!D5:D217,"Specialist centre") | D8: =COUNTIFS('Email Outreach Log'!C:C,A8,'Email Outreach Log'!E:E,B8) | E8: =D8-F8 | F8: =COUNTIFS('Email Outreach Log'!C:C,A8,'Email Outreach Log'!E:E,B8,'Email Outreach Log'!L:L,"Bounced") | G8: =COUNTIFS('Email Outreach Log'!C:C,A8,'Email Outreach Log'!E:E,B8,'Email Outreach Log'!L:L,"Yes") | H8: =COUNTIFS('Email Outreach Log'!C:C,A8,'Email Outreach Log'!E:E,B8,'Email Outreach Log'!L:L,"No")+COUNTIFS('Email Outreach Log'!C:C,A8,'Email Outreach Log'!E:E,B8,'Email Outreach Log'!L:L,"Out of office") | I8: =MAX(C8-D8,0) | J8: =IF(C8=0,0,D8/C8) | K8: Singapore_private
A9: Singapore | B9: GP clinic | C9: =COUNTIF(Singapore_private!D5:D217,"GP clinic") | D9: =COUNTIFS('Email Outreach Log'!C:C,A9,'Email Outreach Log'!E:E,B9) | E9: =D9-F9 | F9: =COUNTIFS('Email Outreach Log'!C:C,A9,'Email Outreach Log'!E:E,B9,'Email Outreach Log'!L:L,"Bounced") | G9: =COUNTIFS('Email Outreach Log'!C:C,A9,'Email Outreach Log'!E:E,B9,'Email Outreach Log'!L:L,"Yes") | H9: =COUNTIFS('Email Outreach Log'!C:C,A9,'Email Outreach Log'!E:E,B9,'Email Outreach Log'!L:L,"No")+COUNTIFS('Email Outreach Log'!C:C,A9,'Email Outreach Log'!E:E,B9,'Email Outreach Log'!L:L,"Out of office") | I9: =MAX(C9-D9,0) | J9: =IF(C9=0,0,D9/C9) | K9: Singapore_private
A10: Taiwan | B10: Dealer | C10: =COUNTA('Taiwan Dealers'!C5:C429) | D10: =COUNTIFS('Email Outreach Log'!C:C,A10,'Email Outreach Log'!E:E,B10) | E10: =D10-F10 | F10: =COUNTIFS('Email Outreach Log'!C:C,A10,'Email Outreach Log'!E:E,B10,'Email Outreach Log'!L:L,"Bounced") | G10: =COUNTIFS('Email Outreach Log'!C:C,A10,'Email Outreach Log'!E:E,B10,'Email Outreach Log'!L:L,"Yes") | H10: =COUNTIFS('Email Outreach Log'!C:C,A10,'Email Outreach Log'!E:E,B10,'Email Outreach Log'!L:L,"No")+COUNTIFS('Email Outreach Log'!C:C,A10,'Email Outreach Log'!E:E,B10,'Email Outreach Log'!L:L,"Out of office") | I10: =MAX(C10-D10,0) | J10: =IF(C10=0,0,D10/C10) | K10: Taiwan Dealers
A11: South Korea | B11: Dealer | C11: =COUNTA('Korea Dealers'!C5:C303) | D11: =COUNTIFS('Email Outreach Log'!C:C,A11,'Email Outreach Log'!E:E,B11) | E11: =D11-F11 | F11: =COUNTIFS('Email Outreach Log'!C:C,A11,'Email Outreach Log'!E:E,B11,'Email Outreach Log'!L:L,"Bounced") | G11: =COUNTIFS('Email Outreach Log'!C:C,A11,'Email Outreach Log'!E:E,B11,'Email Outreach Log'!L:L,"Yes") | H11: =COUNTIFS('Email Outreach Log'!C:C,A11,'Email Outreach Log'!E:E,B11,'Email Outreach Log'!L:L,"No")+COUNTIFS('Email Outreach Log'!C:C,A11,'Email Outreach Log'!E:E,B11,'Email Outreach Log'!L:L,"Out of office") | I11: =MAX(C11-D11,0) | J11: =IF(C11=0,0,D11/C11) | K11: Korea Dealers
A12: Japan | B12: Dealer | C12: =COUNTA('Japan Dealers'!C5:C72) | D12: =COUNTIFS('Email Outreach Log'!C:C,A12,'Email Outreach Log'!E:E,B12) | E12: =D12-F12 | F12: =COUNTIFS('Email Outreach Log'!C:C,A12,'Email Outreach Log'!E:E,B12,'Email Outreach Log'!L:L,"Bounced") | G12: =COUNTIFS('Email Outreach Log'!C:C,A12,'Email Outreach Log'!E:E,B12,'Email Outreach Log'!L:L,"Yes") | H12: =COUNTIFS('Email Outreach Log'!C:C,A12,'Email Outreach Log'!E:E,B12,'Email Outreach Log'!L:L,"No")+COUNTIFS('Email Outreach Log'!C:C,A12,'Email Outreach Log'!E:E,B12,'Email Outreach Log'!L:L,"Out of office") | I12: =MAX(C12-D12,0) | J12: =IF(C12=0,0,D12/C12) | K12: Japan Dealers
A13: TOTAL HUMAN | C13: =SUM(C5:C12) | D13: =SUM(D5:D12) | E13: =SUM(E5:E12) | F13: =SUM(F5:F12) | G13: =SUM(G5:G12) | H13: =SUM(H5:H12) | I13: =SUM(I5:I12) | J13: =IF(C13=0,0,D13/C13)

Sheet Email Outreach Log
A1: EMAIL OUTREACH LOG: every human diagnostics dealer or end user email sent, one row per send
A2: One row per email sent from casper@astramed.sg. Taiwan sends of 6 Oct 2026 logged from the Winmail Sent folder (159 messages); bounces from the Inbox return notices received the same evening.
A4: # | B4: Date sent | C4: Market | D4: Company | E4: Channel | F4: To | G4: CC | H4: Subject | I4: Attachment | J4: Tier | K4: Follow up by | L4: Reply received | M4: Notes
A5: 1 | B5: 06 Oct 2026 | C5: Taiwan | D5: 品約醫療儀器 Pinyork Medical | E5: Dealer | F5: service@pinyork.com.tw | H5: Pinyork Medical: CHISON human diagnostic ultrasound for your clinic base | I5: CHISON Corporate Brochure 2027 (PDF, 2.6 MB) | J5: 1 | K5: 13 Oct 2026 | L5: No | M5: Individual email
A6: 2 | B6: 06 Oct 2026 | C6: Taiwan | D6: 總騰儀器 SOAR Instrument-Tech | E6: Dealer | F6: soar.jimmy@gmail.com | H6: SOAR: CHISON ultrasound for new clinic openings | I6: CHISON Corporate Brochure 2027 (PDF, 2.6 MB) | J6: 1 | K6: 13 Oct 2026 | L6: No | M6: Individual email
A7: 3 | B7: 06 Oct 2026 | C7: Taiwan | D7: 杏恩醫療儀器 Shinn Medical | E7: Dealer | F7: 28262556serv@gmail.com | H7: Shinn Medical: adding ultrasound to your imaging and OR line card | I7: CHISON Corporate Brochure 2027 (PDF, 2.6 MB) | J7: 1 | K7: 13 Oct 2026 | L7: No | M7: Individual email
A8: 4 | B8: 06 Oct 2026 | C8: Taiwan | D8: 承業生醫 CHC Healthcare Group + 久和醫療儀器 ChiuHo Medical | E8: Dealer | F8: Sales.Rt@chcg.com | G8: Sales.Ns@chcg.com | H8: CHC Healthcare Group and ChiuHo Medical: an ultrasound line for your imaging channel | I8: CHISON Corporate Brochure 2027 (PDF, 2.6 MB) | J8: 1 | K8: 13 Oct 2026 | L8: No | M8: Individual email
A9: 5 | B9: 06 Oct 2026 | C9: Taiwan | D9: 巨研科技 GETECH | E9: Dealer | F9: service@getech.com.tw | H9: GETECH: CHISON human diagnostic ultrasound, a tier below your premium line | I9: CHISON Corporate Brochure 2027 (PDF, 2.6 MB) | J9: 2 | K9: 13 Oct 2026 | L9: No | M9: Individual email
A10: 6 | B10: 06 Oct 2026 | C10: Taiwan | D10: 友信行 Yu Hsin Hang (Uni Charm?) · TFDA reg. name: 友信行股份有限公司 | E10: Dealer | F10: info@unison.com.tw | H10: Unison Healthcare Group: CHISON ultrasound as a value tier | I10: CHISON Corporate Brochure 2027 (PDF, 2.6 MB) | J10: 2 | K10: 13 Oct 2026 | L10: No | M10: Individual email
A11: 7 | B11: 06 Oct 2026 | C11: Taiwan | D11: 商之器科技 EBM Technologies | E11: Dealer | F11: info@ebmtech.com | H11: EBM Technologies: pairing CHISON ultrasound with your PACS installed base | I11: CHISON Corporate Brochure 2027 (PDF, 2.6 MB) | J11: 2 | K11: 13 Oct 2026 | L11: No | M11: Individual email
A12: 8 | B12: 06 Oct 2026 | C12: Taiwan | D12: EASTECH 動物超音波 · TFDA reg. name: 華鋒科技股份有限公司 (Eastech) | E12: Dealer | F12: info@eastech-medical.com.tw | H12: Eastech: CHISON handheld and portable ultrasound alongside your current line | I12: CHISON Corporate Brochure 2027 (PDF, 2.6 MB) | J12: 2 | K12: 13 Oct 2026 | L12: No | M12: Individual email
A13: 9 | B13: 06 Oct 2026 | C13: Taiwan | D13: 奇裕企業股份有限公司 | E13: Dealer | F13: info@kromax.com | H13: Kromax: broadening your portable ultrasound line with CHISON | I13: CHISON Corporate Brochure 2027 (PDF, 2.6 MB) | J13: 2 | K13: 13 Oct 2026 | L13: No | M13: Individual email
A14: 10 | B14: 06 Oct 2026 | C14: Taiwan | D14: 力林國際 Vet Supply (crossover) | E14: Dealer | F14: j@vetsupply.com.tw | H14: Vet Supply: CHISON ultrasound for your veterinary customers | I14: CHISON Corporate Brochure 2027 (PDF, 2.6 MB) | J14: 1 | K14: 13 Oct 2026 | L14: No | M14: Individual email
A15: 11 | B15: 06 Oct 2026 | C15: Taiwan | D15: 醫全實業 Yi Chuan Industrial | E15: Dealer | F15: medicare@beam.com.tw | H15: Medicare Products: an ultrasound line for your three regional offices | I15: CHISON Corporate Brochure 2027 (PDF, 2.6 MB) | J15: 2 | K15: 13 Oct 2026 | L15: No | M15: Individual email
A16: 12 | B16: 06 Oct 2026 | C16: Taiwan | D16: 上鉅實業股份有限公司 | E16: Dealer | F16: tphq@sumtage.com.tw | H16: Sumtage: CHISON portable ultrasound alongside your premium imaging lines | I16: CHISON Corporate Brochure 2027 (PDF, 2.6 MB) | J16: 2 | K16: 13 Oct 2026 | L16: No | M16: Individual email
A17: 13 | B17: 06 Oct 2026 | C17: Taiwan | D17: 愛樺企業股份有限公司 (Best Digital) | E17: Dealer | F17: amy@bestimage.com.tw | H17: Best Image: CHISON portable and veterinary ultrasound | I17: CHISON Corporate Brochure 2027 (PDF, 2.6 MB) | J17: 2 | K17: 13 Oct 2026 | L17: No | M17: Individual email
A18: 14 | B18: 06 Oct 2026 | C18: Taiwan | D18: 安泰醫療儀器 Ontai Medical | E18: Dealer | F18: ontaisys@gmail.com | H18: Ontai Medical: CHISON ultrasound for MSK and rehabilitation clinics | I18: CHISON Corporate Brochure 2027 (PDF, 2.6 MB) | J18: 3 | K18: 13 Oct 2026 | L18: No | M18: Individual email
A19: 15 | B19: 06 Oct 2026 | C19: Taiwan | D19: 達進興業有限公司 | E19: Dealer | F19: kuo.green@msa.hinet.net | H19: 達進興業: CHISON portable ultrasound for mobile screening | I19: CHISON Corporate Brochure 2027 (PDF, 2.6 MB) | J19: 2 | K19: 13 Oct 2026 | L19: No | M19: Individual email
A20: 16 | B20: 06 Oct 2026 | C20: Taiwan | D20: 瑋杏儀器有限公司 | E20: Dealer | F20: taichung@goodline.com.tw | H20: 瑋杏儀器: CHISON ultrasound for your Taichung customers | I20: CHISON Corporate Brochure 2027 (PDF, 2.6 MB) | J20: 2 | K20: 13 Oct 2026 | L20: No | M20: Individual email
... A23: 19 | B23: 06 Oct 2026 | C23: Taiwan | D23: 勗曜生技醫材有限公司 | E23: Dealer | F23: p1200.p2200@msa.hinet.net | H23: 勗曜生技醫材: CHISON ultrasound for your operating room customers | I23: CHISON Corporate Brochure 2027 (PDF, 2.6 MB) | J23: 2 | K23: 13 Oct 2026 | L23: No | M23: Individual email
A24: 20 | B24: 06 Oct 2026 | C24: Taiwan | D24: 展銳醫療儀器 + 宇瑞醫療器材 | E24: Dealer | F24: smartech.judy@gmail.com | G24: smartech.tw@gmail.com | H24: 展銳醫療儀器: CHISON ultrasound beside your endoscopy line | I24: CHISON Corporate Brochure 2027 (PDF, 2.6 MB) | J24: 2 | K24: 13 Oct 2026 | L24: No | M24: Individual email
A25: 21 | B25: 06 Oct 2026 | C25: Taiwan | D25: 億眾實業股份有限公司 | E25: Dealer | F25: jamie@mail.bio-drchip.com.tw | H25: 億眾實業: CHISON handheld ultrasound for ambulances and emergency teams | I25: CHISON Corporate Brochure 2027 (PDF, 2.6 MB) | J25: 2 | K25: 13 Oct 2026 | L25: Bounced | M25: Individual email; Domain mail.bio-drchip.com.tw could not be resolved (DNS)
A26: 22 | B26: 06 Oct 2026 | C26: Taiwan | D26: 信隆生技有限公司 | E26: Dealer | F26: sin.lonn@msa.hinet.net | H26: 信隆生技: CHISON ultrasound for emergency and monitoring customers | I26: CHISON Corporate Brochure 2027 (PDF, 2.6 MB) | J26: 2 | K26: 13 Oct 2026 | L26: No | M26: Individual email
A27: 23 | B27: 06 Oct 2026 | C27: Taiwan | D27: 亞帝昇生物科技有限公司 | E27: Dealer | F27: jocdx@yahoo.com.tw | H27: 亞帝昇: CHISON ultrasound for airway and emergency teams | I27: CHISON Corporate Brochure 2027 (PDF, 2.6 MB) | J27: 2 | K27: 13 Oct 2026 | L27: No | M27: Individual email
A28: 24 | B28: 06 Oct 2026 | C28: Taiwan | D28: 中籐實業有限公司 | E28: Dealer | F28: ctm.tw@msa.hinet.net | H28: 中籐實業: adding ultrasound to your X ray and laboratory line | I28: CHISON Corporate Brochure 2027 (PDF, 2.6 MB) | J28: 2 | K28: 13 Oct 2026 | L28: No | M28: Individual email
A29: 25 | B29: 06 Oct 2026 | C29: Taiwan | D29: 偉平貿易有限公司 | E29: Dealer | F29: jane760311@yahoo.com.tw | H29: 偉平貿易: CHISON ultrasound for the clinics you help open | I29: CHISON Corporate Brochure 2027 (PDF, 2.6 MB) | J29: 2 | K29: 13 Oct 2026 | L29: No | M29: Individual email
A30: 26 | B30: 06 Oct 2026 | C30: Taiwan | D30: 健富儀器有限公司 | E30: Dealer | F30: fortunmw@ms49.hinet.net | H30: 健富儀器: CHISON ultrasound for long term care and home care | I30: CHISON Corporate Brochure 2027 (PDF, 2.6 MB) | J30: 2 | K30: 13 Oct 2026 | L30: Bounced | M30: Individual email; Mailbox full (quota exceeded); retry later
A31: 27 | B31: 06 Oct 2026 | C31: Taiwan | D31: 衛康醫療儀器股份有限公司 | E31: Dealer | F31: wecare.medical@msa.hinet.net | H31: 衛康醫療儀器: adding CHISON ultrasound to your line | I31: CHISON Corporate Brochure 2027 (PDF, 2.6 MB) | J31: 2 | K31: 13 Oct 2026 | L31: No | M31: Individual email
A32: 28 | B32: 06 Oct 2026 | C32: Taiwan | D32: 忠杏股份有限公司 | E32: Dealer | F32: tcrtsyst@ms47.hinet.net | H32: 忠杏: CHISON ultrasound for respiratory teams | I32: CHISON Corporate Brochure 2027 (PDF, 2.6 MB) | J32: 2 | K32: 13 Oct 2026 | L32: No | M32: Individual email
A33: 29 | B33: 06 Oct 2026 | C33: Taiwan | D33: 永英有限公司 | E33: Dealer | F33: johnson@winningmedical.com | H33: 永英: CHISON ultrasound for your import and wholesale line | I33: CHISON Corporate Brochure 2027 (PDF, 2.6 MB) | J33: 2 | K33: 13 Oct 2026 | L33: No | M33: Individual email
A34: 30 | B34: 06 Oct 2026 | C34: Taiwan | D34: 優醫有限公司 | E34: Dealer | F34: calvin@whc.com.tw | H34: 優醫: CHISON ultrasound for your import and wholesale line | I34: CHISON Corporate Brochure 2027 (PDF, 2.6 MB) | J34: 2 | K34: 13 Oct 2026 | L34: Bounced | M34: Individual email; Recipient rejected, access denied
A35: 31 | B35: 06 Oct 2026 | C35: Taiwan | D35: 白色牙材 White Dental | E35: Dealer | F35: service@whitedental.com.tw | H35: 誠徵台灣超音波經銷夥伴 | CHISON ultrasound distribution partners in Taiwan | I35: CHISON Corporate Brochure 2027 (PDF, 2.6 MB) | J35: 3 | K35: 13 Oct 2026 | L35: No | M35: Batch 1 of 3, sent separately
A36: 32 | B36: 06 Oct 2026 | C36: Taiwan | D36: 春菖貿易有限公司 | E36: Dealer | F36: ellie@chinaspring.com.tw | H36: 誠徵台灣超音波經銷夥伴 | CHISON ultrasound distribution partners in Taiwan | I36: CHISON Corporate Brochure 2027 (PDF, 2.6 MB) | J36: 3 | K36: 13 Oct 2026 | L36: No | M36: Batch 1 of 3, sent separately; read receipt 7 Oct 2026, no reply yet
... A163: 159 | B163: 06 Oct 2026 | C163: Taiwan | D163: 仲鎂醫療器材有限公司 | E163: Dealer | F163: jm22314315@yahoo.com.tw | H163: 誠徵台灣超音波經銷夥伴 | CHISON ultrasound distribution partners in Taiwan | I163: CHISON Corporate Brochure 2027 (PDF, 2.6 MB) | J163: 3 | K163: 13 Oct 2026 | L163: No | M163: Batch 3 of 3, sent separately

Sheet Taiwan Dealers
A1: Taiwan: Dealer & Channel Targets (424)
A2: Dealer model. Green=Tier1 contact first · Amber=Tier2 qualify · Grey=Tier3 long tail · Pink=REF (competitor/subsidiary, not a target). Rows 1–59 are the original researched list; the block below is the TFDA-registry sweep. TIER RULE (v2's own): Tier 1 needs the right segment, scale/service capability, no obvious competing ultrasound line (or a vet-dedicated channel), AND a working domain. Every tier is justified in the 'Priority rationale' column — see the Priority Audit tab for what changed and why.
A4: # | B4: Company | C4: Pipeline stage | D4: Segment & expertise | E4: Carries ultrasound? | F4: Location | G4: Website | H4: Phone / contact | I4: Fit notes for CHISON | J4: CHISON product focus | K4: Tier | L4: Priority rationale | M4: Source | N4: Email Title | O4: Email Body | P4: Email | Q4: CONTACT CONFIDENCE | R4: Outreach 6 Oct 2026 (Winmail draft) | S4: Visit shortlist
A5: 1 | B5: 品約醫療儀器 Pinyork Medical | C5: Contacted | D5: Ultrasound sales+service, ECG, spirometry, bone density; new & used | E5: Yes — Fujifilm/Aloka, Medisono | F5: Taipei (Neihu) | G5: pinyork.com.tw | H5: (02)2791-5535 · service@pinyork.com.tw | I5: Ultrasound specialist w/ own service team & clinic base; Aloka line aging — openable | J5: SonoGO (3-in-1) + SonoAir 70 as the Aloka-refresh pitch; SonoEye P3 for their clinic accounts | K5: 1 | L5: Tier 1 UPHELD despite carrying Fujifilm/Aloka + Medisono — Aloka is a legacy platform with an ageing installed base, and Pinyork runs its own service team and clinic base. The conflict IS the opportunity: lead the Aloka-refresh pitch. Verified domain + direct phone. | M5: Verified site | N5: Pinyork Medical: CHISON human diagnostic ultrasound for your clinic base | O5: Dear 品約醫療儀器 Pinyork Medical team, I am Casper Tan, Senior Regional Sales Manager at AstraMed Healthcare, a subsidiary of CHISON Medical Technologies, and I look after Taiwan. Following my note of 28 September about our veterinary range, I am writing this time about human diagnostic ultrasound, because Pinyork's own sales and service team and its clinic installed base make you one of the best placed ultrasound specialists in Taiwan. CHISON has designed and built diagnostic ultrasound in Wuxi since 1996, sells in more than 100 countries, and is the only ultrasound maker listed on Shanghai's STAR Market. AstraMed is CHISON's own subsidiary, so you would be working with the manufacturer directly, with no intermediary in between. Regulatory standing of the range: • US FDA: 510(k) clearance, first granted in 2005 • CE: certified since 2002, now under the EU Medical Device Regulation (MDR) • Singapore HSA: SonoMax 9, SonoPort 8, SonoBook 9, SonoAir 70, SonoEye P3 and SonoEye P5 registered, with AstraMed as the local registrant For Taiwan, TFDA registration and the local licence holder role are exactly what I would like to plan together with the right partner. Where much of your installed base runs on ageing Fujifilm and Aloka systems, these are the models I would put forward as the refresh path: • SonoAir 70: a 2.1 kg laptop with four active probe ports and SonoAI tools such as automatic bladder volume and thyroid and breast nodule measurement • SonoGo: a 3 in 1 system with a 15.6 inch full touchscreen, laptop portability at 4.8 kg and a trolley for cart level work • SonoEye P3: a pocket handheld for emergency, ICU and bedside work; SonoEye was rated the top handheld in an independent comparison of nine handheld devices published in Diagnostics (MDPI) I am planning a visit to Taiwan shortly. Would you have 30 minutes for a meeting at your office, or a short call beforehand? Our corporate brochure is attached for your reference. 【中文摘要】祥生醫療 CHISON（1996年創立於無錫，上海科創板上市）正在台灣尋找超音波經銷合作夥伴。產品已取得美國 FDA 510(k)、歐盟 CE（MDR）及新加坡 HSA 註冊。我近期將赴台拜訪，盼能與貴公司見面交流。附件為公司簡介，敬請參閱。 Best regards, Casper Tan Senior Regional Sales Manager (APEC) AstraMed Healthcare A subsidiary of CHISON Medical Technologies +65 8719 0121 | P5: service@pinyork.com.tw | Q5: A: read on pinyork.com.tw (V12 + Winmail sent 28 Sep) | R5: Sent 6 Oct 2026 from Winmail with Corporate Brochure 2027 | S5: VISIT 1: Taipei Neihu
A6: 2 | B6: 巨研科技 GETECH | C6: Contacted | D6: Medical + lab equipment; Philips US distributor (human & VET); vet training programs | E6: Yes — Philips (human+vet) | F6: Kaohsiung/Taichung/Taipei | G6: getech.com.tw | H6: 0800-802-206 | I6: Dual human+vet, nationwide, education muscle; Philips conflict to qualify | J6: VET wedge (no Philips clash): SonoGO vet + SonoEye P3 Vet; human line only if Philips ties loosen | K6: 2 | L6: Tier 2 — carries a line (Yes — Philips (human+vet)) — conflict to qualify · verified domain + direct phone. | M6: Verified site | N6: GETECH: CHISON human diagnostic ultrasound, a tier below your premium line | O6: Dear 巨研科技 GETECH team, I am Casper Tan, Senior Regional Sales Manager at AstraMed Healthcare, a subsidiary of CHISON Medical Technologies, and I look after Taiwan. Following my note of 28 September about veterinary ultrasound, I am writing about the human diagnostic side, where GETECH's nationwide offices and training programmes stand out. CHISON has designed and built diagnostic ultrasound in Wuxi since 1996, sells in more than 100 countries, and is the only ultrasound maker listed on Shanghai's STAR Market. AstraMed is CHISON's own subsidiary, so you would be working with the manufacturer directly, with no intermediary in between. Regulatory standing of the range: • US FDA: 510(k) clearance, first granted in 2005 • CE: certified since 2002, now under the EU Medical Device Regulation (MDR) • Singapore HSA: SonoMax 9, SonoPort 8, SonoBook 9, SonoAir 70, SonoEye P3 and SonoEye P5 registered, with AstraMed as the local registrant For Taiwan, TFDA registration and the local licence holder role are exactly what I would like to plan together with the right partner. I know you represent Philips, so I am not proposing a replacement. If your agreement leaves room, these models sit below a premium cart line rather than against it: • SonoEye P3: a pocket handheld for emergency, ICU and bedside work; SonoEye was rated the top handheld in an independent comparison of nine handheld devices published in Diagnostics (MDPI) • SonoAir 70: a 2.1 kg laptop with four active probe ports and SonoAI tools such as automatic bladder volume and thyroid and breast nodule measurement I am planning a visit to Taiwan shortly. Would you have 30 minutes for a meeting at your office, or a short call beforehand? Our corporate brochure is attached for your reference. 【中文摘要】祥生醫療 CHISON（1996年創立於無錫，上海科創板上市）正在台灣尋找超音波經銷合作夥伴。產品已取得美國 FDA 510(k)、歐盟 CE（MDR）及新加坡 HSA 註冊。我近期將赴台拜訪，盼能與貴公司見面交流。附件為公司簡介，敬請參閱。 Best regards, Casper Tan Senior Regional Sales Manager (APEC) AstraMed Healthcare A subsidiary of CHISON Medical Technologies +65 8719 0121 | P6: service@getech.com.tw | Q6: A: read on getech.com.tw 6 Oct | R6: Sent 6 Oct 2026 from Winmail with Corporate Brochure 2027 | S6: VISIT 8: Kaohsiung
A7: 3 | B7: 總騰儀器 SOAR Instrument-Tech | C7: Contacted | D7: Clinic-opening equipment: US, X-ray, anesthesia, monitors; vet CT line | E7: Yes — GE US | F7: Taiwan | G7: uni-soar.com | H7: via website | I7: Clinic-opening channel + vet crossover; GE line non-exclusive? | 6 Oct 2026 check: uni-soar.com lists a GE ultrasound series alongside Fukuda, Dräger and X-ray; GE conflict is live, email opens with the exclusivity question. | J7: Clinic-opening bundle: SonoEye P3 + EBit 50; SonoGO for premium openings; vet CT cross-sell → EBit 50 Vet | K7: 1 | L7: Tier 1 UPHELD despite carrying GE — the row records the GE line as non-exclusive, and the channel is clinic-opening turnkey bundles, a cost-sensitive buyer where a value-tier brand genuinely wins. Make the GE conflict your first qualifying question. Verified domain. | M7: From search | N7: SOAR: CHISON ultrasound for new clinic openings | O7: Dear 總騰儀器 SOAR team, I am Casper Tan, Senior Regional Sales Manager at AstraMed Healthcare, a subsidiary of CHISON Medical Technologies, and I look after Taiwan. SOAR positions itself as the clinic founder's partner, from X ray and anaesthesia to monitors and the OR, and ultrasound is part of almost every new clinic you equip. CHISON has designed and built diagnostic ultrasound in Wuxi since 1996, sells in more than 100 countries, and is the only ultrasound maker listed on Shanghai's STAR Market. AstraMed is CHISON's own subsidiary, so you would be working with the manufacturer directly, with no intermediary in between. Regulatory standing of the range: • US FDA: 510(k) clearance, first granted in 2005 • CE: certified since 2002, now under the EU Medical Device Regulation (MDR) • Singapore HSA: SonoMax 9, SonoPort 8, SonoBook 9, SonoAir 70, SonoEye P3 and SonoEye P5 registered, with AstraMed as the local registrant For Taiwan, TFDA registration and the local licence holder role are exactly what I would like to plan together with the right partner. I know you carry GE ultrasound, so my first question is whether that agreement is exclusive. If it is not, these are the models I would offer as an entry tier for openings on a tighter budget: • SonoEye P3: a pocket handheld for emergency, ICU and bedside work; SonoEye was rated the top handheld in an independent comparison of nine handheld devices published in Diagnostics (MDPI) • SonoAir 70: a 2.1 kg laptop with four active probe ports and SonoAI tools such as automatic bladder volume and thyroid and breast nodule measurement • SonoGo: a 3 in 1 system with a 15.6 inch full touchscreen, laptop portability at 4.8 kg and a trolley for cart level work I am planning a visit to Taiwan shortly. Would you have 30 minutes for a meeting at your office, or a short call beforehand? Our corporate brochure is attached for your reference. 【中文摘要】祥生醫療 CHISON（1996年創立於無錫，上海科創板上市）正在台灣尋找超音波經銷合作夥伴。產品已取得美國 FDA 510(k)、歐盟 CE（MDR）及新加坡 HSA 註冊。我近期將赴台拜訪，盼能與貴公司見面交流。附件為公司簡介，敬請參閱。 Best regards, Casper Tan Senior Regional Sales Manager (APEC) AstraMed Healthcare A subsidiary of CHISON Medical Technologies +65 8719 0121 | P7: soar.jimmy@gmail.com | Q7: A: read on uni-soar.com contact page 6 Oct | R7: Sent 6 Oct 2026 from Winmail with Corporate Brochure 2027 | S7: VISIT 4: New Taipei Xizhi
A8: 4 | B8: 杏恩醫療儀器 Shinn Medical | C8: Contacted | D8: Devices, equipment, consumables; agent for DE/UK brands | E8: Unknown | F8: Taiwan | G8: shinn.com.tw | H8: via website | I8: Broad importer incl. X-ray, monitors, OR items — no visible US brand | J8: SonoMax 7 + SonoPort for radiology; XBit 90 premium rooms | K8: 1 | L8: Tier 1 — line card unqualified — ask first · verified domain. | M8: From search | N8: Shinn Medical: adding ultrasound to your imaging and OR line card | O8: Dear 杏恩醫療儀器 Shinn Medical team, I am Casper Tan, Senior Regional Sales Manager at AstraMed Healthcare, a subsidiary of CHISON Medical Technologies, and I look after Taiwan. Shinn already imports X ray, monitoring and OR equipment from European brands, and I could not find an ultrasound system on your line card, which is why I am writing. CHISON has designed and built diagnostic ultrasound in Wuxi since 1996, sells in more than 100 countries, and is the only ultrasound maker listed on Shanghai's STAR Market. AstraMed is CHISON's own subsidiary, so you would be working with the manufacturer directly, with no intermediary in between. Regulatory standing of the range: • US FDA: 510(k) clearance, first granted in 2005 • CE: certified since 2002, now under the EU Medical Device Regulation (MDR) • Singapore HSA: SonoMax 9, SonoPort 8, SonoBook 9, SonoAir 70, SonoEye P3 and SonoEye P5 registered, with AstraMed as the local registrant For Taiwan, TFDA registration and the local licence holder role are exactly what I would like to plan together with the right partner. For a radiology and hospital channel without an ultrasound line today, these are the models I would start with: • SonoPort: a cart that folds to 1 m high and weighs about 53 kg, with a 23.8 inch monitor, a 15.6 inch touchscreen and about 3 hours of scanning on battery • SonoAir 70: a 2.1 kg laptop with four active probe ports and SonoAI tools such as automatic bladder volume and thyroid and breast nodule measurement • SonoEye P3: a pocket handheld for emergency, ICU and bedside work; SonoEye was rated the top handheld in an independent comparison of nine handheld devices published in Diagnostics (MDPI) I am planning a visit to Taiwan shortly. Would you have 30 minutes for a meeting at your office, or a short call beforehand? Our corporate brochure is attached for your reference. 【中文摘要】祥生醫療 CHISON（1996年創立於無錫，上海科創板上市）正在台灣尋找超音波經銷合作夥伴。產品已取得美國 FDA 510(k)、歐盟 CE（MDR）及新加坡 HSA 註冊。我近期將赴台拜訪，盼能與貴公司見面交流。附件為公司簡介，敬請參閱。 Best regards, Casper Tan Senior Regional Sales Manager (APEC) AstraMed Healthcare A subsidiary of CHISON Medical Technologies +65 8719 0121 | P8: 28262556serv@gmail.com | Q8: A: read on shinn.com.tw 6 Oct | R8: Sent 6 Oct 2026 from Winmail with Corporate Brochure 2027 | S8: VISIT 3: Taipei
A9: 5 | B9: 派瑞勒生醫 Petrichor Biomed | C9: Not started | D9: Handheld/wireless US & imaging distributor | E9: Yes — ASUS handheld, Konica | F9: Taiwan | G9: ptpetrichor.com.tw | H9: via website | I9: POCUS-native channel; ASUS conflict to qualify | 6 Oct 2026 check: domain ptpetrichor.com.tw redirects to a different company (倍可有限公司 Bei Ke Medcare). Not emailed. Bei Ke Medcare is now its own row (#424). | J9: SonoMax 7 + SonoPort for radiology; XBit 90 premium rooms | K9: 2 | L9: Tier 2 — carries a line (Yes — ASUS handheld, Konica) — conflict to qualify · verified domain. | M9: From search | N9: CHISON ultrasound for 派瑞勒生醫 Petrichor Biomed: a line-card addition, with TFDA handled by us | O9: Dear 派瑞勒生醫 Petrichor Biomed team, I am Casper Tan, Senior Regional Sales Manager at AstraMed Healthcare, the CHISON Medical Technologies subsidiary responsible for this region. I am building the Taiwan channel this year. CHISON has manufactured diagnostic ultrasound in Wuxi, China since 1996, sells into more than 100 countries and is the only ultrasound manufacturer listed on China's STAR Market (688358). The platform carries CE and US FDA clearance. As AstraMed is the manufacturer's own subsidiary rather than an importer, you would be dealing with the factory directly, with no intermediary margin between us. Your position in this category is already established: Handheld/wireless ultrasound & imaging distributor. You will therefore assess a new line faster than most, and on the criteria that actually matter: image quality, probe life and service turnaround. Where CHISON fits your portfolio: you already sell ultrasound, so this is a second-brand question rather than a new-category question. CHISON is priced to win the accounts your current line is too expensive for: • SonoMax 7: the flagship cart, carrying a full radiology, obstetric and cardiac workload • SonoPort: our new-generation intelligent cart, launched April 2026 • XBit 90: premium cart for departments that want high-end imaging without a high-end budget That gives you a focused cart offer. If you let me know which brand you carry today, I will show you exactly where CHISON sits against it rather than take up your time on a general presentation. On the commercial side we carry what usually slows a new line down. TFDA Class II registration and QSD/UDI support are handled by us, together with application training for your sales team, a demonstration unit for your first accounts, and spare parts and probe stock held regionally so that your service engineers are never waiting on the factory. Would a short call of twenty minutes be worth your time? I can send the full catalogue, price positioning and dealer terms beforehand, so that the call is a decision rather than a presentation. Best regards, Casper Tan Senior Regional Sales Manager AstraMed Healthcare, a subsidiary of CHISON Medical Technologies | Q9: NOT CONFIRMED: ptpetrichor.com.tw now redirects to 倍可有限公司 Bei Ke Medcare (beikemd.com.tw, BKMD@beikemd.com). Verify which company trades before contacting
A10: 6 | B10: 安泰醫療儀器 Ontai Medical | C10: Contacted | D10: US + rehab/therapy devices | E10: Yes — therapy US | F10: Taiwan | G10: ontai.com.tw | H10: via website | I10: MSK/rehab niche for portable | J10: Lead SonoGO (new 3-in-1) + SonoEye vs incumbent line; SonoAir 70 premium portable | K10: 3 | L10: Tier 3 — carries a line (Yes — therapy US) — conflict to qualify · verified domain. | M10: From search | N10: Ontai Medical: CHISON ultrasound for MSK and rehabilitation clinics | O10: Dear 安泰醫療儀器 Ontai Medical team, I am Casper Tan, Senior Regional Sales Manager at AstraMed Healthcare, a subsidiary of CHISON Medical Technologies, and I look after Taiwan. Ontai serves rehabilitation and therapy clinics, where diagnostic ultrasound for tendons, joints and guided injections is now part of everyday work. CHISON has designed and built diagnostic ultrasound in Wuxi since 1996, sells in more than 100 countries, and is the only ultrasound maker listed on Shanghai's STAR Market. AstraMed is CHISON's own subsidiary, so you would be working with the manufacturer directly, with no intermediary in between. Regulatory standing of the range: • US FDA: 510(k) clearance, first granted in 2005 • CE: certified since 2002, now under the EU Medical Device Regulation (MDR) • Singapore HSA: SonoMax 9, SonoPort 8, SonoBook 9, SonoAir 70, SonoEye P3 and SonoEye P5 registered, with AstraMed as the local registrant For Taiwan, TFDA registration and the local licence holder role are exactly what I would like to plan together with the right partner. For MSK and rehabilitation customers, these are the models I would suggest: • SonoEye P5: a phone paired handheld with high frequency imaging for MSK, vascular access and small parts • SonoAir 70: a 2.1 kg laptop with four active probe ports and SonoAI tools such as automatic bladder volume and thyroid and breast nodule measurement I am planning a visit to Taiwan shortly. Would you have 30 minutes for a meeting at your office, or a short call beforehand? Our corporate brochure is attached for your reference. 【中文摘要】祥生醫療 CHISON（1996年創立於無錫，上海科創板上市）正在台灣尋找超音波經銷合作夥伴。產品已取得美國 FDA 510(k)、歐盟 CE（MDR）及新加坡 HSA 註冊。我近期將赴台拜訪，盼能與貴公司見面交流。附件為公司簡介，敬請參閱。 Best regards, Casper Tan Senior Regional Sales Manager (APEC) AstraMed Healthcare A subsidiary of CHISON Medical Technologies +65 8719 0121 | P10: ontaisys@gmail.com | Q10: A: read on ontai.com.tw 6 Oct | R10: Sent 6 Oct 2026 from Winmail with Corporate Brochure 2027
A11: 7 | B11: 京華超音波 KSonic | C11: Not started | D11: Therapeutic ultrasound devices | E11: Yes — therapy only | F11: Taiwan | G11: ksonic.com.tw | H11: via website | I11: Physio channel; diagnostic US = new line for them | J11: Lead SonoGO (new 3-in-1) + SonoEye vs incumbent line; SonoAir 70 premium portable | K11: 3 | L11: Tier 3 — carries a line (Yes — therapy only) — conflict to qualify · verified domain. | M11: From search | N11: General-imaging ultrasound alongside your current line: CHISON for 京華超音波 KSonic | O11: Dear 京華超音波 KSonic team, I am Casper Tan, Senior Regional Sales Manager at AstraMed Healthcare, the CHISON Medical Technologies subsidiary responsible for this region. I am building the Taiwan channel this year. CHISON has manufactured diagnostic ultrasound in Wuxi, China since 1996, sells into more than 100 countries and is the only ultrasound manufacturer listed on China's STAR Market (688358). The platform carries CE and US FDA clearance. As AstraMed is the manufacturer's own subsidiary rather than an importer, you would be dealing with the factory directly, with no intermediary margin between us. Yours is a specialised line: Therapeutic ultrasound devices. Specialists sell with real credibility, though a single-application system does cap what you are able to quote into an account once you have won it. Where CHISON fits your portfolio: general diagnostic imaging is the open gap beside your current line. The same clinicians, a considerably broader indication set: • SonoGO: launched July 2026, the first 3-in-1 platform, working as tablet, laptop and trolley in one system with SonoAI on board • SonoEye: pocket handheld for bedside point-of-care scanning • SonoAir 70: the lightest laptop scanner in its class None of it competes with what you already represent. It simply allows you to quote a second system into an account you have already won, with two portable formats at two very different budgets. On the commercial side we carry what usually slows a new line down. TFDA Class II registration and QSD/UDI support are handled by us, together with application training for your sales team, a demonstration unit for your first accounts, and spare parts and probe stock held regionally so that your service engineers are never waiting on the factory. If this is worth a look, I would welcome fifteen or twenty minutes to compare line cards and establish where the fit sits. I am happy to send the catalogue and indicative dealer pricing ahead of the call. Best regards, Casper Tan Senior Regional Sales Manager AstraMed Healthcare, a subsidiary of CHISON Medical Technologies
A12: 8 | B12: Broadsound Corporation | C12: Contacted | D12: US transducers & imaging (ITRI spin-off); 90+ country export | E12: Yes — own probes | F12: Hsinchu | G12: broadsound.com.tw | H12: via website | I12: Probe/service partner rather than clinic dealer | J12: SonoMax 7 + SonoPort for radiology; XBit 90 premium rooms | K12: 3 | L12: Tier 3 — carries a line (Yes — own probes) — conflict to qualify · verified domain. | M12: From search | N12: CHISON ultrasound for Broadsound Corporation: a line-card addition, with TFDA handled by us | O12: Dear Broadsound Corporation team, I am Casper Tan, Senior Regional Sales Manager at AstraMed Healthcare, the CHISON Medical Technologies subsidiary responsible for this region. I am building the Taiwan channel this year. CHISON has manufactured diagnostic ultrasound in Wuxi, China since 1996, sells into more than 100 countries and is the only ultrasound manufacturer listed on China's STAR Market (688358). The platform carries CE and US FDA clearance. As AstraMed is the manufacturer's own subsidiary rather than an importer, you would be dealing with the factory directly, with no intermediary margin between us. Your position in this category is already established: ultrasound transducers & imaging (ITRI spin-off), 90 and country export. You will therefore assess a new line faster than most, and on the criteria that actually matter: image quality, probe life and service turnaround. Where CHISON fits your portfolio: you already sell ultrasound, so this is a second-brand question rather than a new-category question. CHISON is priced to win the accounts your current line is too expensive for: • SonoMax 7: the flagship cart, carrying a full radiology, obstetric and cardiac workload • SonoPort: our new-generation intelligent cart, launched April 2026 • XBit 90: premium cart for departments that want high-end imaging without a high-end budget That gives you a focused cart offer. If you let me know which brand you carry today, I will show you exactly where CHISON sits against it rather than take up your time on a general presentation. On the commercial side we carry what usually slows a new line down. TFDA Class II registration and QSD/UDI support are handled by us, together with application training for your sales team, a demonstration unit for your first accounts, and spare parts and probe stock held regionally so that your service engineers are never waiting on the factory. If this is worth a look, I would welcome fifteen or twenty minutes to compare line cards and establish where the fit sits. I am happy to send the catalogue and indicative dealer pricing ahead of the call. Best regards, Casper Tan Senior Regional Sales Manager AstraMed Healthcare, a subsidiary of CHISON Medical Technologies | P12: info@broadsound.com.tw | Q12: A: read on broadsound.com.tw 6 Oct | R12: Batch draft 1 of 3 (Send separately) sent 6 Oct 2026
A13: 9 | B13: 台灣大昌華嘉 DKSH Taiwan | C13: Not started | D13: Market expansion giant — healthcare devices distribution (347 TFDA records / 40 foreign mfrs) | E13: Portfolio varies | F13: Taipei | G13: dksh.com | H13: via website | I13: Full-service market entry incl. regulatory + salesforce; premium cost | J13: Registration scope: SonoEye P3/P5 + SonoBook 9 + SonoMax 7 first | K13: 1 | L13: Tier 1 — line card unqualified — ask first · verified domain. | M13: Directory (TFDA) | N13: A full ultrasound ladder for 台灣大昌華嘉 DKSH Taiwan: CHISON distribution in Taiwan | O13: Dear 台灣大昌華嘉 DKSH Taiwan team, I am Casper Tan, Senior Regional Sales Manager at AstraMed Healthcare, the CHISON Medical Technologies subsidiary responsible for this region. I am building the Taiwan channel this year. CHISON has manufactured diagnostic ultrasound in Wuxi, China since 1996, sells into more than 100 countries and is the only ultrasound manufacturer listed on China's STAR Market (688358). The platform carries CE and US FDA clearance. As AstraMed is the manufacturer's own subsidiary rather than an importer, you would be dealing with the factory directly, with no intermediary margin between us. Yours is the model foreign manufacturers turn to when they want a market entered properly rather than cheaply: Market expansion giant, healthcare devices distribution. That is exactly what we are looking for here. Where CHISON fits your portfolio: this is a full ladder rather than a single product, which suits a house that carries whole categories: • SonoEye P3: pocket handheld for emergency, intensive care and bedside point-of-care scanning • SonoBook 9: the workhorse laptop and our volume seller across Asia • SonoMax 7: the flagship cart, carrying a full radiology, obstetric and cardiac workload One principal agreement then covers the tender, the departmental purchase and the clinic purchase, giving you a complete handheld to cart ladder under one supplier agreement. On the commercial side we carry what usually slows a new line down. TFDA Class II registration and QSD/UDI support are handled by us, together with application training for your sales team, a demonstration unit for your first accounts, and spare parts and probe stock held regionally so that your service engineers are never waiting on the factory. Would a short call of twenty minutes be worth your time? I can send the full catalogue, price positioning and dealer terms beforehand, so that the call is a decision rather than a presentation. Best regards, Casper Tan Senior Regional Sales Manager AstraMed Healthcare, a subsidiary of CHISON Medical Technologies | Q13: Not published: enquiry route via dksh.com/tw-zh-Hant/home/healthcare/direct-contact-hec | S13: VISIT 5: Taipei (form first)
