Workbook
Name Stage_List: '02_Pipeline_Stages'!$B$5:$B$13

Sheet READ ME
B1: CHISON VETERINARY ULTRASOUND: DEALER & END-USER TARGET LIST v17
B2: Japan · South Korea · Taiwan · Singapore | Companion animal, exotics, equine and production animal | Casper Tan, Senior Regional Sales Manager, AstraMed Healthcare (a subsidiary of CHISON) | 27 Sep 2026
B4: WHAT CHANGED IN v11 (27 Sep 2026) | C4: 1. EMAIL CHECK: every email domain in the workbook was tested for a live mail server (DNS MX). 58 of 60 passed. Two Singapore clinic addresses bounce (Animal Infirmary, The Pet Doctors) and were removed. 2. CONTACTS RE-OPENED: company sites were re-opened for Japan, Korea and Taiwan rows missing email; 8 new confirmed emails added (Shine Kochi, OpenVet, GETECH, KogiPet, Pinyork, Yu Chiang, Hungan, Rayence phone) and MUNATEX upgraded from D to A. 3. NEW TARGETS: 16 Japan (mainly the regional opening support dealers on Mikasa X-ray's national dealer map, giving coverage in Tohoku, Hokkaido, Tokai, Kansai, Chugoku, Shikoku and Okinawa), 3 Korea, 2 Taiwan, and a NEW Singapore Dealers tab with 4 targets. 4. CORRECTIONS: Tokushima Iryoki carries Hitachi Aloka, Canon and Fujifilm, so moved to Tier 2; KogiPet and Pinyork moved to Tier 3 (see Corrections Log C-v11). 5. EMAILS: all 270 plus ready to send emails rewritten to your title and signature (casper@astramed.sg), em and en dashes removed, dealer pricing offer removed, and Singapore clinic emails no longer promise direct supply. 6. Former dealers AJJ, Medical Plus, AMF and Smitch Tech added to the Reference tab as DO NOT APPOINT.
B5: OUTREACH STATUS (29 Sep 2026) | C5: 45 prospects emailed on 28 Sep 2026 from casper@astramed.sg with the CHISON VET introduction attached, checked against the Winmail Sent folder on 29 Sep: Korea 5 dealers (POSKOM, JPI Healthcare, VSI, BlueVet, VETON), Taiwan 8 dealers (OpenVet, AHOSS, GETECH, Guojien, KogiPet, Hungan, Meijin, Pinyork), Singapore 3 dealers (Sage Healthcare, Vedmed Agri, Singapore Veterinary Imaging) and 29 Singapore end user clinics. 4 bounced, 1 real reply (AAVC), 3 auto replies. Every send is on the Outreach Log tab, with a new Channel column (Dealer or End user), and the new Outreach Summary tab counts them by market. Follow up date 5 Oct 2026. Japan: no emails yet. Still to email in Taiwan: Shine Kochi, Tengpon, Vet Supply, Vetnostrum, YoChung, YUMAX, Best Digital, ISVD. Korea: clear new contacts with Jerry first.
B6: WHAT v11 COULD NOT VERIFY | C6: a) The Korean government registry of 2,646 licensed veterinary device sellers (data.go.kr dataset 15045052) could not be downloaded from here; download it by hand, it is the best source for more Korean dealers. b) The QIA licensed importer list is blocked to automated readers. c) Singapore Vet show exhibitor list is not public; ask singaporevet@closerstillmedia.com. d) Several Japanese regional dealer sites (Nactol, Tech Mikasa, Goodwill Medical, Sanko, marukou11) would not load, so they are graded C. e) No named individual has been verified anywhere, except sales contacts published on a company's own page.
B7: WHAT THIS WORKBOOK IS | C7: One consolidated target list for CHISON veterinary ultrasound across four markets, built by merging four earlier workbooks (TargetList v5, Workbook v2.0, Market Development Target List v2 and the Top 10 Engagement List) and then re-checking every row for whether it can actually buy. There are no duplicates: two rows that turned out to be one company have been merged, and the collapse of every source row is logged on the Merge Log tab. Every organisation on an outreach tab has a subject line and an email body written for that specific company, ready to copy and send.
B8: HOW TO USE IT IN THE MORNING | C8: 1. Open the tab for the market you are working. 2. Filter the BUYING POTENTIAL column to HIGH. 3. Read the two background and fit-note columns: that is your thirty seconds of preparation. 4. Check the CONTACT CONFIDENCE column: A means the phone or email came off the company's own page; D means confirm the company exists first. 5. Copy the last two columns into your mail client and send. Nothing needs editing except your own signature block if you prefer a different one.
B9: WHAT CHANGED IN v9: RE-VERIFICATION OF THE MARKET DEVELOPMENT TARGET LIST v3 | C9: The whole of CHISON_Market_Development_Target_List_v3 was re-checked against this workbook, row by row. 1. THE FOUR VETERINARY TABS ARE ALREADY HERE. All 205 rows on the v3 VET Taiwan / VET Korea / VET Japan / VET Singapore tabs were traced into this workbook: every one is already present on a target tab, on Channel Resources, or on Reference: Do Not Contact. Nothing was missing and nothing new was added from them. The full row-by-row trace is on the new 'v9 Reconciliation (MDv3)' tab. 2. THE HUMAN-DIAGNOSTIC TABS WERE MINED FOR VETERINARY CROSSOVER: this is where the value was. The v3 file also carries ~245 HUMAN diagnostic dealer rows that had never been read for veterinary relevance. Six companies on them turned out to have a real veterinary business, and every one has been live-checked and added: JPI Healthcare and Mediana (Korea), Best Digital (Taiwan), Inter Medical (Japan), Sage Healthcare (Singapore), plus DK Medical Systems carried with a correction. One more, the ASUS handheld distributor, went to Reference. 3. THREE STRUCTURAL DEFECTS IN v8 WERE REPAIRED: see the row below. 4. Six new organisations, each with a bespoke ready-to-send email.
B10: DEFECTS IN v8 REPAIRED IN v9: READ THIS IF YOU USED THE v8 COUNTS | C10: a) EVERY TIER, PRIORITY, BUYING-POTENTIAL AND CONTACT-CONFIDENCE COUNT IN v8 WAS WRONG, and almost all of them read zero. When v8 inserted the four pipeline columns (Pipeline Stage, Owner, Next Action, Next Action Date) at column D, every column from D rightwards shifted four places: but the COUNTIF formulas under each table were not moved with them. They were still counting tiers in the contact-confidence column and priorities in the email column. All 66 of them have been repointed to the correct columns and now show real numbers. If you quoted any v8 count to anyone, re-check it here. b) COLUMN WIDTHS WERE STALE BY THE SAME FOUR COLUMNS. 'Email template', which holds a single letter, was 88 characters wide, while 'Email body': the column you actually copy from: was 13. Widths on all seven target tabs have been realigned to the headers they now sit under. c) FREEZE PANES WERE MISSING OR WRONG on three tabs. The v8 READ ME states that column D sits inside the frozen panes on every target tab; in fact Japan Dealers and Singapore End Users had no freeze at all, and Korea End Users & KOL was frozen at R21. All seven are now frozen at H5, so # / company / stage / owner / next action stay on screen while you scroll right.
B11: WHAT THE v9 PASS DID NOT DO | C11: It did not re-verify the rows already in v8: those still carry the confidence grades and source notes they were given in v6 and v7, and the open items on the 'WHAT IS STILL NOT VERIFIED' row below all still stand. It did not add the nine v3 rows that were research tasks rather than organisations (southern-Korea regional dealers, the Gyeonggi-North / Incheon veterinary associations, the 쿨펫/웰펫 franchise names, the Tokyo 24-hour cluster, 'ONE for Animals'-style consolidators, online CE platforms, prefectural veterinary associations and the Royal Canin / Hill's rep networks): they are listed on the reconciliation tab as open tasks, because a row with no confirmed entity behind it cannot carry an email. And no named individual has been verified at any company in this workbook: that is still true, and still the single biggest gap.
B12: WHAT CHANGED IN v7 | C12: 1. NEW COLUMN: 'Company / Organisation background': what each company actually does, its scale and history, and one explicit sentence on why it is relevant to CHISON. Column D on every outreach tab. 2. NEW COLUMN: 'BUYING / DISTRIBUTION POTENTIAL': a plain verdict (HIGH / MEDIUM / LOW) with the reason and the regulatory timing, so you can sort the list by who can actually transact. 3. NON-BUYERS REMOVED FROM THE OUTREACH TABS: 13 organisations that cannot buy (competitors, brand subsidiaries, competitor distribution channels, one wound-down operation and one research task) moved to a new 'Reference: Do Not Contact' tab. Every remaining row on every outreach tab is sendable. 4. NEW TAB: 'Why These Contacts': the relevance logic for each type of row, and what would disqualify it. 5. FOUR RESEARCH CORRECTIONS applied: see the row below. 6. READ ME rewritten.
B13: CORRECTIONS MADE DURING THE v7 RELEVANCE CHECK | C13: a) EASTECH (Taiwan) was carried as a Tier 3 dealer candidate. Opening eastech-medical.com showed it is 華鋒科技, the SOLE TAIWAN AGENT FOR ESAOTE, selling handheld, portable AND cart veterinary ultrasound plus veterinary MRI, majority-owned by BenQ Medical Technology within the Qisda group. It is a competitor channel, not a recruit. Moved to Reference. b) 'Animal Recovery Veterinary Referral Centre' and 'Pet Space Singapore' were TWO ROWS FOR ONE COMPANY: Animal Recovery Veterinary Centre Pte Ltd was formerly Pet Space (Singapore) Pte Ltd. Merged into one P1 row, and upgraded: the group runs 12 clinics across Hong Kong and Singapore and already offers both ultrasound and a HOUSE-CALL service, which is the strongest handheld argument there is. c) Singapore Turf Club Equine Hospital: horse racing in Singapore ended on 5 October 2024 and the Kranji site is being returned to the state. Not a realistic buyer. Moved to Reference. d) The AS-1 / ASCO duplicate flag raised in v6 is RESOLVED: ASCO Corporation is a Sala Group company in Toyohashi with 22 branches, so the two are different companies. ASCO was also upgraded: their own site states they sell instruments and machinery, not only drugs. e) SOAR Instrument-Tech (Taiwan) was downgraded from Tier 1 to Tier 2: uni-soar.com returned no content when fetched, so the 'no ultrasound in the catalogue' claim is unverified. It returns to Tier 1 the moment that is confirmed.
B14: CHANNEL MODEL PER MARKET: READ BEFORE ANY EMAIL | C14: v11 UPDATE: as agreed with Jerry, all four markets are developed primarily through dealers. SINGAPORE: dealer led, with AstraMed (CHISON's own subsidiary) supporting installation, training and service; veterinary health products sit outside the Health Products Act device regime, confirm with AVS. JAPAN: dealers may be approached freely; MAFF foreign manufacturer registration, a Japanese MAH and NVAL notification are needed before any order. SOUTH KOREA: discuss each distributor with Jerry first; a Korean entity must hold a QIA veterinary device import licence. TAIWAN: no animal only device registration identified; the open question is customs import permission for Chinese origin goods. Former dealers AJJ, Medical Plus, AMF and Smitch Tech will not be reappointed.
B15: WHY THESE CONTACTS ARE RELEVANT: THE SHORT VERSION | C15: Dealers were selected on one test: do they already sell into animal hospitals, and do they have NO competing ultrasound line? That produces four repeating profiles: the imaging dealer with X-ray or CT but no ultrasound, the clinic-opening trading house that writes the equipment list, the animal-drug wholesaler whose rep is in every clinic weekly, and the surgical dealer whose customer wants peri-operative imaging. Dealers who DO carry ultrasound are graded Tier 2 with one rule: pocket tier only, never a competing console. End users were selected on where a handheld actually gets used: emergency floors, house calls, feline and exotic practice, multi-site groups that decide once and repeat, and teaching hospitals that set habits for a decade. The full logic, profile by profile, is on the 'Why These Contacts' tab.
... B18: PRODUCT CONSTRAINT: DECISION D-2 | C18: Twelve veterinary SKUs exist at USD 5,299 to 21,200 US list, and there is NO veterinary-labelled cart. Referral hospitals and university teaching hospitals must be led with handheld and portable units. Do not promise a veterinary cart to any account before D-2 resolves.
B20: COVERAGE
B21: Japan: dealer targets | D21: =COUNTA('Japan Dealers'!B5:B48)
B22: South Korea: dealer targets | D22: =COUNTA('Korea Dealers'!B5:B36)
B23: Taiwan: dealer targets | D23: =COUNTA('Taiwan Dealers'!B5:B30)
B24: Singapore: dealer targets (new in v11) | D24: =COUNTA('Singapore Dealers'!B5:B8)
B25: Singapore: end-user clinic accounts | D25: =COUNTA('Singapore End Users'!B5:B78)
B26: Japan: end-user and KOL accounts | D26: =COUNTA('Japan End Users & KOL'!B5:B32)
B27: South Korea: end-user and KOL accounts | D27: =COUNTA('Korea End Users & KOL'!B5:B30)
B28: Taiwan: end-user and KOL accounts | D28: =COUNTA('Taiwan End Users & KOL'!B5:B51)
B29: TOTAL CONTACTABLE ORGANISATIONS, all with a ready to send email | D29: =SUM(D21:D28)
B30: Dealer rows with a confirmed email address in column N (all four dealer tabs) | D30: =COUNTIF('Japan Dealers'!N5:N48,"*@*")+COUNTIF('Korea Dealers'!N5:N36,"*@*")+COUNTIF('Taiwan Dealers'!N5:N30,"*@*")+COUNTIF('Singapore Dealers'!N5:N8,"*@*")
B31: Registries, associations and research tasks (Channel Resources) | D31: =COUNTA('Channel Resources'!B5:B29)
B32: Competitors, non-buyers and former dealers (Reference, no email) | D32: =COUNTA('Reference — Do Not Contact'!B5:B23)
B33: Search strings, registries and directories | D33: =COUNTA('Search Terms'!C5:C50)
B34: Master email frames | D34: =COUNTA('Email Templates'!A5:A18)
B36: TIER AND PRIORITY KEY
B37: TIER 1 / P1 | C37: Contact first: right segment, real capability, no competing ultrasound line.
B38: TIER 2 / P2 | C38: Qualify first: strong channel but a competing line, or fit unconfirmed.
B39: TIER 3 / P3 | C39: Long tail, niche or regional fill-in.
B40: MFR | C40: Manufacturer or supplier selling INTO dealers. Complementary-line or OEM talk only: never a distribution appointment.
B41: BUYING POTENTIAL: HIGH | C41: Real budget, right customer, and either can transact today (Singapore) or is appoint-grade the moment the market gate clears.
B42: BUYING POTENTIAL: MEDIUM | C42: A genuine buyer or partner, but something needs qualifying first: a competing line, an unconfirmed entity, or a slow cycle.
B43: BUYING POTENTIAL: LOW | C43: Long tail, niche, or a partnership rather than a purchase. Work only after everything above it.
B44: VERIFY FIRST | C44: Entity or operating status not confirmed. Check before spending time.
B46: TAB GUIDE
...

Sheet 02_Pipeline_Stages
A1: PIPELINE STAGES — THE SINGLE SOURCE FOR EVERY STAGE DROPDOWN
A2: These nine stages are not new. They are the same nine already in use in the 'Response' dropdown on the Top 10 Engage Now tab, so the whole workbook tracks progress in one vocabulary. They now populate the 'Pipeline Stage' dropdown in column D of all seven target tabs — Japan / Korea / Taiwan Dealers, Singapore End Users, and the three End Users & KOL tabs. THIS SHEET IS THE REFERENCE: what each stage means and what colour it turns. The dropdowns themselves carry the nine names inline, the same way the Top 10 Engage Now dropdown always has, so they need nothing else in the workbook to resolve and work in any version of Excel. To change a stage name, edit it here and then update the validations: select column D, Data ▸ Data Validation, edit the Source line, and repeat on each tab — or ask Claude to regenerate the workbook, which is faster. Renaming a stage does not rewrite stages already chosen on the tabs; use Find & Replace across the workbook if you rename one mid-campaign.
A4: # | B4: Pipeline stage (this column IS the dropdown list) | C4: What it means — the test for moving a row into this stage | D4: Colour on the tabs
A5: 1 | B5: Not started | C5: On the list, no approach made yet. Every row starts here.
A6: 2 | B6: Contacted | C6: First approach sent — the ready-to-send email on this row, or an equivalent call or LinkedIn touch. No reply yet.
A7: 3 | B7: Meeting booked | C7: They came back and a call or a visit is in the diary.
A8: 4 | B8: Meeting held | C8: Call or visit done. Segment fit, decision route and budget understood.
A9: 5 | B9: Evaluation placed | C9: A unit is with the dealer or the account for hands-on trial, clinical evaluation or a seminar demo. Check the Engagement rules tab first — outside Singapore there are things you may not yet ship or quote.
A10: 6 | B10: Quoted | C10: Formal pricing issued — unit price, dealer terms or an opening package.
A11: 7 | B11: Won | C11: Dealer appointed, or end-user purchase order received. Hand over to account management.
A12: 8 | B12: Declined | C12: Ruled out — competitor lock-in, wrong segment, no budget, entity unverifiable, or they said no.
A13: 9 | B13: Parked | C13: A real target at the wrong moment. Held with a review date — not the same as Declined.
B15: HOW THE TABS USE THIS | C15: Column D on each target tab is a dropdown, pre-set to 'Not started' on every existing row and colour-coded to the swatches above. Column D sits inside the frozen panes, so the stage stays on screen while you scroll right through contact details and the ready-to-send email columns. Stage is included in each tab's AutoFilter — filter column D to work one stage at a time.
B16: BEFORE YOU MOVE ANYTHING TO 'QUOTED' | C16: Read the Engagement rules tab. Singapore is the only market where you may quote, invoice and install today. In Taiwan, South Korea and Japan there is a gating action outstanding, so 'Evaluation placed' and 'Quoted' carry conditions — do not move a row into them on autopilot.
B18: OWNER, NEXT ACTION AND NEXT ACTION DATE | C18: Added directly after Pipeline Stage on every target tab, so the whole working record lives in this one workbook. The funnel dashboard reads them: a row past 'Not started' with no next action, no owner, or a date in the past is flagged as needing attention. All three are optional — leave them blank and the dashboard simply omits those fields.

Sheet Outreach Summary
A1: EMAIL OUTREACH SUMMARY BY MARKET: VETERINARY
A2: Counts are live formulas on the Outreach Log and the target tabs. Source checked against the casper@astramed.sg Winmail Sent folder on 29 Sep 2026. Human diagnostics outreach is tracked in CHISON_Market_Development_Target_List_v6.xlsx.
A4: Market | B4: Channel | C4: Targets on list | D4: Emails sent | E4: Delivered | F4: Bounced | G4: Replied | H4: Auto reply / no reply yet | I4: Follow up due by | J4: Still to email | K4: % of list emailed | L4: Target tab
A5: Singapore | B5: Dealer | C5: =COUNTA('Singapore Dealers'!D5:D8) | D5: =COUNTIFS('Outreach Log'!C:C,A5,'Outreach Log'!N:N,B5) | E5: =D5-F5 | F5: =COUNTIFS('Outreach Log'!C:C,A5,'Outreach Log'!N:N,B5,'Outreach Log'!L:L,"Bounced") | G5: =COUNTIFS('Outreach Log'!C:C,A5,'Outreach Log'!N:N,B5,'Outreach Log'!L:L,"Yes") | H5: =COUNTIFS('Outreach Log'!C:C,A5,'Outreach Log'!N:N,B5,'Outreach Log'!L:L,"No")+COUNTIFS('Outreach Log'!C:C,A5,'Outreach Log'!N:N,B5,'Outreach Log'!L:L,"Out of office") | I5: =IF(H5=0,"",_xlfn.MINIFS('Outreach Log'!K:K,'Outreach Log'!C:C,A5,'Outreach Log'!N:N,B5,'Outreach Log'!L:L,"No")) | J5: =MAX(C5-D5,0) | K5: =IF(C5=0,0,D5/C5) | L5: Singapore Dealers
A6: Singapore | B6: End user | C6: =COUNTA('Singapore End Users'!D5:D78) | D6: =COUNTIFS('Outreach Log'!C:C,A6,'Outreach Log'!N:N,B6) | E6: =D6-F6 | F6: =COUNTIFS('Outreach Log'!C:C,A6,'Outreach Log'!N:N,B6,'Outreach Log'!L:L,"Bounced") | G6: =COUNTIFS('Outreach Log'!C:C,A6,'Outreach Log'!N:N,B6,'Outreach Log'!L:L,"Yes") | H6: =COUNTIFS('Outreach Log'!C:C,A6,'Outreach Log'!N:N,B6,'Outreach Log'!L:L,"No")+COUNTIFS('Outreach Log'!C:C,A6,'Outreach Log'!N:N,B6,'Outreach Log'!L:L,"Out of office") | I6: =IF(H6=0,"",_xlfn.MINIFS('Outreach Log'!K:K,'Outreach Log'!C:C,A6,'Outreach Log'!N:N,B6,'Outreach Log'!L:L,"No")) | J6: =MAX(C6-D6,0) | K6: =IF(C6=0,0,D6/C6) | L6: Singapore End Users
A7: Taiwan | B7: Dealer | C7: =COUNTA('Taiwan Dealers'!D5:D30) | D7: =COUNTIFS('Outreach Log'!C:C,A7,'Outreach Log'!N:N,B7) | E7: =D7-F7 | F7: =COUNTIFS('Outreach Log'!C:C,A7,'Outreach Log'!N:N,B7,'Outreach Log'!L:L,"Bounced") | G7: =COUNTIFS('Outreach Log'!C:C,A7,'Outreach Log'!N:N,B7,'Outreach Log'!L:L,"Yes") | H7: =COUNTIFS('Outreach Log'!C:C,A7,'Outreach Log'!N:N,B7,'Outreach Log'!L:L,"No")+COUNTIFS('Outreach Log'!C:C,A7,'Outreach Log'!N:N,B7,'Outreach Log'!L:L,"Out of office") | I7: =IF(H7=0,"",_xlfn.MINIFS('Outreach Log'!K:K,'Outreach Log'!C:C,A7,'Outreach Log'!N:N,B7,'Outreach Log'!L:L,"No")) | J7: =MAX(C7-D7,0) | K7: =IF(C7=0,0,D7/C7) | L7: Taiwan Dealers
A8: Taiwan | B8: End user | C8: =COUNTA('Taiwan End Users & KOL'!D5:D51) | D8: =COUNTIFS('Outreach Log'!C:C,A8,'Outreach Log'!N:N,B8) | E8: =D8-F8 | F8: =COUNTIFS('Outreach Log'!C:C,A8,'Outreach Log'!N:N,B8,'Outreach Log'!L:L,"Bounced") | G8: =COUNTIFS('Outreach Log'!C:C,A8,'Outreach Log'!N:N,B8,'Outreach Log'!L:L,"Yes") | H8: =COUNTIFS('Outreach Log'!C:C,A8,'Outreach Log'!N:N,B8,'Outreach Log'!L:L,"No")+COUNTIFS('Outreach Log'!C:C,A8,'Outreach Log'!N:N,B8,'Outreach Log'!L:L,"Out of office") | I8: =IF(H8=0,"",_xlfn.MINIFS('Outreach Log'!K:K,'Outreach Log'!C:C,A8,'Outreach Log'!N:N,B8,'Outreach Log'!L:L,"No")) | J8: =MAX(C8-D8,0) | K8: =IF(C8=0,0,D8/C8) | L8: Taiwan End Users & KOL
A9: South Korea | B9: Dealer | C9: =COUNTA('Korea Dealers'!D5:D36) | D9: =COUNTIFS('Outreach Log'!C:C,A9,'Outreach Log'!N:N,B9) | E9: =D9-F9 | F9: =COUNTIFS('Outreach Log'!C:C,A9,'Outreach Log'!N:N,B9,'Outreach Log'!L:L,"Bounced") | G9: =COUNTIFS('Outreach Log'!C:C,A9,'Outreach Log'!N:N,B9,'Outreach Log'!L:L,"Yes") | H9: =COUNTIFS('Outreach Log'!C:C,A9,'Outreach Log'!N:N,B9,'Outreach Log'!L:L,"No")+COUNTIFS('Outreach Log'!C:C,A9,'Outreach Log'!N:N,B9,'Outreach Log'!L:L,"Out of office") | I9: =IF(H9=0,"",_xlfn.MINIFS('Outreach Log'!K:K,'Outreach Log'!C:C,A9,'Outreach Log'!N:N,B9,'Outreach Log'!L:L,"No")) | J9: =MAX(C9-D9,0) | K9: =IF(C9=0,0,D9/C9) | L9: Korea Dealers
A10: South Korea | B10: End user | C10: =COUNTA('Korea End Users & KOL'!D5:D30) | D10: =COUNTIFS('Outreach Log'!C:C,A10,'Outreach Log'!N:N,B10) | E10: =D10-F10 | F10: =COUNTIFS('Outreach Log'!C:C,A10,'Outreach Log'!N:N,B10,'Outreach Log'!L:L,"Bounced") | G10: =COUNTIFS('Outreach Log'!C:C,A10,'Outreach Log'!N:N,B10,'Outreach Log'!L:L,"Yes") | H10: =COUNTIFS('Outreach Log'!C:C,A10,'Outreach Log'!N:N,B10,'Outreach Log'!L:L,"No")+COUNTIFS('Outreach Log'!C:C,A10,'Outreach Log'!N:N,B10,'Outreach Log'!L:L,"Out of office") | I10: =IF(H10=0,"",_xlfn.MINIFS('Outreach Log'!K:K,'Outreach Log'!C:C,A10,'Outreach Log'!N:N,B10,'Outreach Log'!L:L,"No")) | J10: =MAX(C10-D10,0) | K10: =IF(C10=0,0,D10/C10) | L10: Korea End Users & KOL
A11: Japan | B11: Dealer | C11: =COUNTA('Japan Dealers'!D5:D48) | D11: =COUNTIFS('Outreach Log'!C:C,A11,'Outreach Log'!N:N,B11) | E11: =D11-F11 | F11: =COUNTIFS('Outreach Log'!C:C,A11,'Outreach Log'!N:N,B11,'Outreach Log'!L:L,"Bounced") | G11: =COUNTIFS('Outreach Log'!C:C,A11,'Outreach Log'!N:N,B11,'Outreach Log'!L:L,"Yes") | H11: =COUNTIFS('Outreach Log'!C:C,A11,'Outreach Log'!N:N,B11,'Outreach Log'!L:L,"No")+COUNTIFS('Outreach Log'!C:C,A11,'Outreach Log'!N:N,B11,'Outreach Log'!L:L,"Out of office") | I11: =IF(H11=0,"",_xlfn.MINIFS('Outreach Log'!K:K,'Outreach Log'!C:C,A11,'Outreach Log'!N:N,B11,'Outreach Log'!L:L,"No")) | J11: =MAX(C11-D11,0) | K11: =IF(C11=0,0,D11/C11) | L11: Japan Dealers
A12: Japan | B12: End user | C12: =COUNTA('Japan End Users & KOL'!D5:D32) | D12: =COUNTIFS('Outreach Log'!C:C,A12,'Outreach Log'!N:N,B12) | E12: =D12-F12 | F12: =COUNTIFS('Outreach Log'!C:C,A12,'Outreach Log'!N:N,B12,'Outreach Log'!L:L,"Bounced") | G12: =COUNTIFS('Outreach Log'!C:C,A12,'Outreach Log'!N:N,B12,'Outreach Log'!L:L,"Yes") | H12: =COUNTIFS('Outreach Log'!C:C,A12,'Outreach Log'!N:N,B12,'Outreach Log'!L:L,"No")+COUNTIFS('Outreach Log'!C:C,A12,'Outreach Log'!N:N,B12,'Outreach Log'!L:L,"Out of office") | I12: =IF(H12=0,"",_xlfn.MINIFS('Outreach Log'!K:K,'Outreach Log'!C:C,A12,'Outreach Log'!N:N,B12,'Outreach Log'!L:L,"No")) | J12: =MAX(C12-D12,0) | K12: =IF(C12=0,0,D12/C12) | L12: Japan End Users & KOL
A13: TOTAL VET | C13: =SUM(C5:C12) | D13: =SUM(D5:D12) | E13: =SUM(E5:E12) | F13: =SUM(F5:F12) | G13: =SUM(G5:G12) | H13: =SUM(H5:H12) | I13: =MIN(I5:I12) | J13: =SUM(J5:J12) | K13: =IF(C13=0,0,D13/C13)
A15: BY MARKET, DEALERS AND END USERS COMBINED
A16: Market | B16: Emails sent | C16: Bounced | D16: Replied | E16: Still to email
A17: Singapore | B17: =SUMIF(A$5:A$12,A17,D$5:D$12) | C17: =SUMIF(A$5:A$12,A17,F$5:F$12) | D17: =SUMIF(A$5:A$12,A17,G$5:G$12) | E17: =SUMIF(A$5:A$12,A17,J$5:J$12)
A18: Taiwan | B18: =SUMIF(A$5:A$12,A18,D$5:D$12) | C18: =SUMIF(A$5:A$12,A18,F$5:F$12) | D18: =SUMIF(A$5:A$12,A18,G$5:G$12) | E18: =SUMIF(A$5:A$12,A18,J$5:J$12)
A19: South Korea | B19: =SUMIF(A$5:A$12,A19,D$5:D$12) | C19: =SUMIF(A$5:A$12,A19,F$5:F$12) | D19: =SUMIF(A$5:A$12,A19,G$5:G$12) | E19: =SUMIF(A$5:A$12,A19,J$5:J$12)
A20: Japan | B20: =SUMIF(A$5:A$12,A20,D$5:D$12) | C20: =SUMIF(A$5:A$12,A20,F$5:F$12) | D20: =SUMIF(A$5:A$12,A20,G$5:G$12) | E20: =SUMIF(A$5:A$12,A20,J$5:J$12)
A22: NOTES FROM THE SENT FOLDER CHECK (29 Sep 2026)
A23: 1. 45 prospects emailed, all on 28 Sep 2026: Korea 5 dealers, Taiwan 8 dealers, Singapore 3 dealers and 29 Singapore end user clinics. Japan: none yet.
A24: 2. Bounced (4): The Animal Doctors, The Veterinary Clinic, Animal World Veterinary Clinic, Spring Veterinary Care. Phone numbers for a working email are on the Singapore End Users tab.
A25: 3. Real reply (1): AAVC asked for price; you replied on 29 Sep proposing a meeting in Yishun.
A26: 4. Auto replies (3): Amber Vet, Vet Central, Pets Avenue. Pets Avenue has moved to hello@petsavenuevet.com.
A27: 5. Sent twice: JPI Healthcare (Korea) and Amber Vet (Singapore). Counted once here.
A28: 6. Corrected: Animal Practice Pte Ltd was marked Contacted but no email to it is in the Sent folder. Reset to Not started.
A29: 7. Human diagnostics: no dealer or end user emails sent yet.

Sheet Japan Dealers
A1: JAPAN — VETERINARY DEALER / DISTRIBUTOR TARGETS
A2: Dealer model. Two columns at the far right hold a ready-to-send email for each company. Japan requires CHISON foreign-manufacturer registration with MAFF, a Japanese marketing authorisation holder and an NVAL marketing notification before any quote or order — note that Arrow Medical, KIRIKAN and Medical Space all hold veterinary device marketing-authorisation licences of their own, which is why they rank where they do.
A4: # | B4: Company (local name) | C4: Company (roman/EN) | D4: Pipeline Stage | E4: Owner | F4: Next Action | G4: Next Action Date | H4: Company background — what they do, and why it matters to CHISON | I4: Segment & expertise | J4: Carries an ultrasound line? | K4: Location / coverage | L4: Website (URL) | M4: Phone / fax | N4: Email | O4: Address & company detail | P4: CONTACT CONFIDENCE | Q4: Why this dealer for CHISON VET (fit notes) | R4: CHISON VET product to lead with | S4: Tier | T4: BUYING / DISTRIBUTION POTENTIAL | U4: Email template | V4: Source status | W4: Email subject — ready to send | X4: Email body — ready to send (copy/paste)
A5: 1 | B5: アローメディカル株式会社 | C5: Arrow Medical Co., Ltd. | D5: Not started | H5: Yokohama-based veterinary trading house founded 1978, selling nationwide to small-animal clinics. Sole Japan agent for Welch Allyn veterinary diagnostic instruments — otoscopes, ophthalmoscopes, laryngoscopes, thermometers, stethoscopes, exam lighting — plus supplements. Runs the 'WAO' clinic-opening support programme and has been involved in over a thousand new-clinic and refurbishment projects, and exhibits at JSVAS. RELEVANCE: they write the equipment list at the exact moment a vet is deciding what to buy, and there is no ultrasound anywhere in their published range — so a handheld is pure additional margin with zero channel conflict. | I5: Veterinary total trading house. Sole Japan agent for Welch Allyn veterinary diagnostic instruments; otoscopes, ophthalmoscopes, laryngoscopes, thermometers, stethoscopes, exam lighting, supplements. Runs the 'WAO' clinic-opening support programme and Japan's first vet-dedicated showroom (AMCC). | J5: NO — none visible in the published product line | K5: Nationwide; founded 1978 | L5: https://www.arrowmedical.co.jp | M5: TEL 045-481-7471 · FAX 045-481-7554 | N5: mail@arrowmedical.co.jp | O5: 〒221-0865 横浜市神奈川区片倉4-7-28 (CEO 矢野修二) | P5: A — VERIFIED DIRECT (phone + email off company profile page) | Q5: The single cleanest recruit in Japan. Deep small-animal clinic access, zero ultrasound conflict, and 1,000+ new-clinic / rebuild projects means they specify the whole equipment list at the moment a vet is deciding. A handheld is the natural first scanner in an opening package. Exhibits at JSVAS, so there is a neutral place to meet. DECISIVE NEW FACT: they hold a Class-3 veterinary device MARKETING AUTHORISATION licence (第三種動物用医療機器製造販売業), a veterinary device MANUFACTURING licence, a veterinary device REPAIR licence and a veterinary drug wholesale licence. That means they could plausibly act as the Japanese marketing authorisation holder rather than merely resell — which is the single biggest obstacle on the Japan gating list. They sell to roughly 3,000 practising vets plus Azabu University, Yamazaki Gakuen and the Yokohama, Kanazawa and Nogeyama zoos. | R5: SonoEye P3 VET (opening package) + EBit 50 VET | S5: TIER 1 | T5: HIGH — appoint-grade. No competing ultrasound line, and they already specify full equipment lists. | U5: A | V5: Verified — company profile page fetched 4 Aug 2026 | W5: Arrow Medical Co., Ltd.: a first scanner for the clinics you equip | X5: Dear アローメディカル株式会社 (Arrow Medical Co., Ltd.) team, My name is Casper Tan, Senior Regional Sales Manager at AstraMed Healthcare, a subsidiary of CHISON Medical Technologies. I cover Japan, South Korea, Taiwan and Singapore for CHISON veterinary ultrasound. I am writing to Arrow Medical Co., Ltd. specifically, not to a list. You have supported more than a thousand clinic openings and rebuilds since 1978, you sell to around three thousand practising veterinarians, and, the part that made me write, you hold a Class-3 veterinary device marketing authorisation, a manufacturing licence and a repair licence. Very few companies in Japan could both carry our line and hold the authorisation for it. CHISON makes veterinary ultrasound built around handheld and portable form factors, proper vet presets, micro-convex, linear and rectal probes, at a price well under GE, Fujifilm, Canon and Mindray. That matters most at the moment a practice is being equipped, because it turns ultrasound from a line item that gets deferred into one that fits the opening budget. For context: we have no appointed veterinary distributor in Japan and would rather build one than sell around one. The product I would put in front of you first is the SonoEye P3 VET (opening package) and EBit 50 VET. Would twenty minutes in the next fortnight be useful? I can send the veterinary line card beforehand if you would rather look before you talk. Best regards, Casper Tan Senior Regional Sales Manager AstraMed Healthcare, a subsidiary of CHISON Medical Technologies casper@astramed.sg | +65 8719 0121
A6: 2 | B6: ムナテックス株式会社 | C6: MUNATEX Corporation | D6: Not started | H6: Nationwide veterinary total trading company carrying everything from disposables and injection needles up to advanced imaging equipment, with an animal-hospital opening-support arm. RELEVANCE: the disposables business puts their rep inside every clinic on a weekly cycle, which is the cheapest demo route that exists for a pocket scanner, and the opening-support arm gives them first-fit influence. Confirm on the first call whether any ultrasound already sits in the imaging range. | I6: Veterinary total trading company: disposables and injection needles through to advanced imaging equipment; animal-hospital opening support service. | J6: NO · none in the 11 published categories (X-ray, CR and DR are listed) | K6: Japan, nationwide | L6: https://munatex.com/products/ | M6: TEL 049-256-3611 · FAX 049-256-3612 · order FAX 0120-279717 (weekdays 09:00 to 17:30) | N6: Not published; enquiry via munatex.com | O6: 〒356-0050 埼玉県ふじみ野市ふじみ野4-9-12 | P6: A · VERIFIED DIRECT (phone and fax off the products page, opened 27 Sep 2026) | Q6: v11 CHECK: products page opened 27 Sep 2026 lists X-ray, CR and DR but no ultrasound, so archetype F applies. Full-range vet trading house with an opening-support arm — same structural fit as Arrow Medical and a good second horse in the same race. Their disposables business gives them weekly contact with every clinic, which is the cheapest possible demo route for a handheld. | R6: SonoGO VET + SonoEye P3 VET | S6: TIER 1 | T6: HIGH — same structural fit as Arrow Medical; a sound second horse in the same race. | U6: A | V6: Verified 27 Sep 2026 · products page fetched | W6: MUNATEX Corporation: a first scanner for the clinics you equip | X6: Dear ムナテックス株式会社 (MUNATEX Corporation) team, My name is Casper Tan, Senior Regional Sales Manager at AstraMed Healthcare, a subsidiary of CHISON Medical Technologies. I cover Japan, South Korea, Taiwan and Singapore for CHISON veterinary ultrasound. I am writing to MUNATEX Corporation specifically, not to a list. You cover animal hospitals from disposables right through to advanced imaging, and you run an opening-support arm alongside it. That combination, daily contact through consumables plus involvement at the moment a clinic specifies its equipment, is exactly where a first scanner gets chosen. CHISON makes veterinary ultrasound built around handheld and portable form factors, proper vet presets, micro-convex, linear and rectal probes, at a price well under GE, Fujifilm, Canon and Mindray. That matters most at the moment a practice is being equipped, because it turns ultrasound from a line item that gets deferred into one that fits the opening budget. For context: we have no appointed veterinary distributor in Japan and would rather build one than sell around one. The product I would put in front of you first is the SonoGO VET and SonoEye P3 VET. Would twenty minutes in the next fortnight be useful? I can send the veterinary line card beforehand if you would rather look before you talk. Best regards, Casper Tan Senior Regional Sales Manager AstraMed Healthcare, a subsidiary of CHISON Medical Technologies casper@astramed.sg | +65 8719 0121
A7: 3 | B7: 株式会社キリカン洋行 | C7: KIRIKAN Ltd. | D7: Not started | H7: Tokyo import trading house founded 1973 for small-animal pharmaceuticals, devices and materials. Line card includes ALSA (Italy) electrosurgery, Integra LifeSciences surgical instruments, and Ortho Medical (Germany) and INTRAUMA (Italy) orthopaedic implants. RELEVANCE: importing foreign medical brands is their core competence, so the manufacturer file and the regulatory legwork are routine for them. A handheld sells into a conversation they are already having — vascular access, nerve block, peri-operative FAST — rather than competing with anything on the shelf. | I7: Import trading house founded 1973 for small-animal pharmaceuticals, devices and materials. Line card: ALSA (Italy) electrosurgery ADC140/ADC200SP, Integra LifeSciences surgical instruments, Ortho Medical (Germany) and INTRAUMA (Italy) orthopaedic implants, Nolvasan, Malaseb. | J7: NO — surgical, orthopaedic and materials only | K7: Tokyo HQ; national | L7: https://www.kirikan.com · onlinestore.kirikan.com | M7: Not published on the site — call switchboard via site | N7: Not published — enquiry via onlinestore.kirikan.com | O7: 〒108-0075 東京都港区港南5-4-12 横浜倉庫7F (CEO 村松慶一) | P7: B — VERIFIED PARTIAL (address confirmed; no phone/email published) | Q7: Surgical and orthopaedic depth with no imaging line at all. A handheld sells into their existing conversation — vascular access, nerve block, peri-operative FAST — rather than competing with anything they already carry. Import trading is their core competence, so a foreign manufacturer file is routine work for them. DECISIVE NEW FACT: they hold a Class-2 veterinary device marketing authorisation licence (第二種動物用医療機器製造販売業) plus veterinary device manufacturing, repair and wholesale licences — so they too could carry the Japanese MAH role. 50+ years importing veterinary product from the US, Italy, Australia, Germany and Austria (Zoetis, Dermcare, alsa, iM3, Integra, Sontec, Intrauma, IMEX, Burton, panno-med), and they sell not only to vets but to other veterinary device WHOLESALERS — a second layer of reach. | R7: SonoEye P3 VET (peri-op / nerve block) + SonoAir 30 VET | S7: TIER 1 | T7: HIGH — surgical and orthopaedic depth with no imaging line to defend. | U7: C | V7: Verified — company profile page fetched 4 Aug 2026 | W7: KIRIKAN Ltd.: ultrasound guidance for the surgery you already equip | X7: Dear 株式会社キリカン洋行 (KIRIKAN Ltd.) team, My name is Casper Tan, Senior Regional Sales Manager at AstraMed Healthcare, a subsidiary of CHISON Medical Technologies. I cover Japan, South Korea, Taiwan and Singapore for CHISON veterinary ultrasound. I am writing to KIRIKAN Ltd. specifically, not to a list. You have spent fifty years importing veterinary product into Japan from Zoetis, Dermcare, alsa, iM3, Integra, Intrauma, IMEX and panno-med, you hold a Class-2 veterinary device marketing authorisation, and you sell not only to veterinarians but to other veterinary device wholesalers. You also have no ultrasound in the line card. CHISON's SonoEye P3 VET is a pocket-sized veterinary scanner built for ultrasound-guided nerve blocks, vascular access in a collapsed patient and a ninety-second pre-anaesthetic FAST. It stays in theatre instead of living in another room, and it does not overlap with anything in your line card. For context: we have no appointed veterinary distributor in Japan and would rather build one than sell around one. The product I would put in front of you first is the SonoEye P3 VET (peri-op / nerve block) and SonoAir 30 VET. Are you open to a short call? I would rather show you the block and the vascular-access demo than describe them. Best regards, Casper Tan Senior Regional Sales Manager AstraMed Healthcare, a subsidiary of CHISON Medical Technologies casper@astramed.sg | +65 8719 0121
A8: 4 | B8: ミズホ株式会社（動物医療部門） | C8: MIZUHO Corporation — Animal Medical Division | D8: Not started | H8: Established Japanese manufacturer of human operating-room equipment (OR tables, neurosurgical systems) that runs a dedicated animal medical division selling veterinary operating tables and surgical and orthopaedic instruments. RELEVANCE: the human-OR brand carries real weight with veterinary surgeons, and their customer is precisely the vet who wants peri-operative imaging. Attaching a pocket scanner to an operating-table sale is high-margin and conflicts with nothing they carry. | I8: Established human operating-room manufacturer (OR tables, neurosurgery) with a dedicated animal-hospital device division: vet operating tables, orthopaedic and general surgical instruments. | J8: NO | K8: Tokyo; national | L8: https://www.mizuho.co.jp/animal/ | M8: TEL 0120-88-7554 (小動物課 / Small Animal Dept — freephone) | N8: Not published — catalogue request form on the animal page | O8: Japan (Tokyo HQ) | P8: A — VERIFIED DIRECT (dedicated small-animal department freephone) | Q8: Brand credibility from the human OR side, sold into vet operating rooms. Adding a pocket scanner to an OR-table sale is a high-margin attachment with no channel conflict, and their surgical customer is exactly the vet who wants peri-operative imaging. | R8: SonoEye P3 VET + SonoTouch VET | S8: TIER 1 | T8: HIGH — operating-room credibility, no imaging conflict. | U8: C | V8: Re-verified 27 Sep 2026 · animal page confirms surgical tables and orthopaedics, no ultrasound | W8: MIZUHO Corporation: Animal Medical Division, ultrasound guidance for the surgery you already equip | X8: Dear ミズホ株式会社 (MIZUHO Corporation) team, My name is Casper Tan, Senior Regional Sales Manager at AstraMed Healthcare, a subsidiary of CHISON Medical Technologies. I cover Japan, South Korea, Taiwan and Singapore for CHISON veterinary ultrasound. I am writing to MIZUHO Corporation specifically, not to a list. You bring operating-room credibility from the human side into veterinary theatres, and your animal division sells the tables and instruments that surgery runs on, but not imaging. A pocket scanner attaches to that sale rather than competing with it. CHISON's SonoEye P3 VET is a pocket-sized veterinary scanner built for ultrasound-guided nerve blocks, vascular access in a collapsed patient and a ninety-second pre-anaesthetic FAST. It stays in theatre instead of living in another room, and it does not overlap with anything in your line card. For context: we have no appointed veterinary distributor in Japan and would rather build one than sell around one. The product I would put in front of you first is the SonoEye P3 VET and SonoTouch VET. Are you open to a short call? I would rather show you the block and the vascular-access demo than describe them. Best regards, Casper Tan Senior Regional Sales Manager AstraMed Healthcare, a subsidiary of CHISON Medical Technologies casper@astramed.sg | +65 8719 0121
A9: 5 | B9: 日本全薬工業株式会社（ゼノアック） | C9: Nippon Zenyaku Kogyo Co., Ltd. (ZENOAQ) | D9: Not started | H9: Major Fukushima-headquartered animal-health company doing R&D, manufacture, import, export and sale of veterinary drugs AND veterinary medical devices, selling into small-animal hospitals, livestock clinics, livestock bodies and overseas distributors, and running Asia roadshows. RELEVANCE: the widest veterinary reach of any company on this tab, and — critically for Japan — an existing import/export function, which means they could carry the Japanese marketing authorisation holder role rather than merely reselling. The livestock arm makes bovine reproduction scanning a second revenue line for the same product. | I9: Major Japanese animal-health company: R&D, manufacture, import/export and sale of veterinary drugs AND veterinary medical devices. Customers span small-animal hospitals, livestock clinics, livestock bodies and overseas distributors. Runs Asia roadshow seminars (seen running events in Taiwan via ivetmall). | J9: Not identified — confirm | K9: Fukushima HQ; nationwide + Asia | L9: https://www.zenoaq.com | M9: Not published (site suppresses telephone detection) | N9: PARTNERSHIP FORM — zenoaq.com/contact/business-development/ (new business, new products, business alliances). Companion animal: zenoaq.com/contact/ca/ | O9: 〒963-0196 福島県郡山市安積町笹川字平ノ上1番地の1 (CEO 福井寿一 · 706 staff · ¥46.6bn FY2025) | P9: A — VERIFIED DIRECT (dedicated business-development enquiry route) | Q9: The widest vet reach of any company on this list and an existing import/export function — meaning they can plausibly carry the Japanese marketing-authorisation-holder role, not just resell. Livestock arm makes bovine repro scanning a second revenue line for the same product. | R9: SonoEye P3 VET (companion) + EBit 50 VET (bovine repro) | S9: TIER 1 | T9: HIGH — the one Japanese candidate that could plausibly hold the marketing-authorisation-holder role. | U9: E | V9: Verified site | W9: Nippon Zenyaku Kogyo Co., Ltd. (ZENOAQ): capital margin on the relationship you already pay for | X9: Dear 日本全薬工業株式会社 (Nippon Zenyaku Kogyo Co., Ltd.) team, My name is Casper Tan, Senior Regional Sales Manager at AstraMed Healthcare, a subsidiary of CHISON Medical Technologies. I cover Japan, South Korea, Taiwan and Singapore for CHISON veterinary ultrasound. I am writing to Nippon Zenyaku Kogyo Co., Ltd. specifically, not to a list. You research, manufacture, import, export and sell both veterinary pharmaceuticals and veterinary devices, across companion animal and livestock, and you run seminar programmes across Asia. The import and export function is the reason I am writing: we need a Japanese partner who can carry a marketing authorisation, not only resell. CHISON's veterinary range is designed to be carried and demonstrated by a rep who is already in the building, no installation crew, no site survey. A unit demonstrated on a Tuesday can be quoted on the Tuesday. It is capital margin layered onto a relationship you already pay for. For context: we have no appointed veterinary distributor in Japan and would rather build one than sell around one. The product I would put in front of you first is the SonoEye P3 VET (companion) and EBit 50 VET (bovine repro). Could we find twenty minutes? Best regards, Casper Tan Senior Regional Sales Manager AstraMed Healthcare, a subsidiary of CHISON Medical Technologies casper@astramed.sg | +65 8719 0121
A10: 6 | B10: 株式会社アスコ | C10: ASCO Corporation | D10: Not started | H10: Specialist animal-health trading company founded 1949, part of the Sala Group (Toyohashi). Sells veterinary pharmaceuticals, instruments and equipment (動物用医薬品・器具器材・機械設備) through 22 branches nationwide, across two divisions: production animals for livestock farmers, and small animals for veterinary hospitals. The name stands for Animal-health Service & Consulting. RELEVANCE: this was previously assumed to be a drugs-and-consumables channel. Their own corporate site names equipment and machinery explicitly, which upgrades them considerably — 22 branches selling equipment to both livestock and companion-animal customers matches the whole CHISON VET range, handheld and EBit 50 alike. | I10: Specialist trading house for veterinary pharmaceuticals: drugs, therapeutic diets, reagents and medical devices supplied to animal hospitals, with total practice-operation support. | J10: Not identified — confirm | K10: Japan (Sala group) | L10: https://www.asco.sala.jp/companion-animal/ | M10: Not published on the companion-animal page — check asco.sala.jp corporate contact | N10: Not published — enquiry via site | O10: Japan (Sala group) | P10: B — VERIFIED PARTIAL (page opened and live; no phone/email published there) | Q10: A pharma-and-consumables channel with a standing weekly order relationship at every clinic. Capital equipment is incremental margin on a relationship they already pay for. Low friction to place an evaluation unit because their rep is already in the building. | R10: SonoEye P3 VET (rep-carried demo unit) | S10: TIER 1 | T10: HIGH — VERIFIED AUGUST 2026: their own site states they sell equipment and machinery, not only drugs. 22 branches. | U10: E | V10: Verified site (search-indexed) | W10: ASCO Corporation: capital margin on the relationship you already pay for | X10: Dear 株式会社アスコ (ASCO Corporation) team, My name is Casper Tan, Senior Regional Sales Manager at AstraMed Healthcare, a subsidiary of CHISON Medical Technologies. I cover Japan, South Korea, Taiwan and Singapore for CHISON veterinary ultrasound. I am writing to ASCO Corporation specifically, not to a list. Your representatives are inside small-animal hospitals every week on drugs, therapeutic diets and reagents, and you already supply medical devices alongside them. That standing relationship is the cheapest demo route for a handheld that exists in Japan. CHISON's veterinary range is designed to be carried and demonstrated by a rep who is already in the building, no installation crew, no site survey. A unit demonstrated on a Tuesday can be quoted on the Tuesday. It is capital margin layered onto a relationship you already pay for. For context: we have no appointed veterinary distributor in Japan and would rather build one than sell around one. The product I would put in front of you first is the SonoEye P3 VET (rep-carried demo unit). Could we find twenty minutes? Best regards, Casper Tan Senior Regional Sales Manager AstraMed Healthcare, a subsidiary of CHISON Medical Technologies casper@astramed.sg | +65 8719 0121
A11: 7 | B11: 株式会社メディカルスペース | C11: Medical Space Inc. | D11: Not started | H11: Veterinary equipment dealer that also plans, builds and refurbishes animal hospitals, with a showroom and a used-equipment trade. Line card includes GE HealthCare Japan, Canon Medtech Supply, Fujifilm and Fujifilm Medical, Konica Minolta and esaote veterinary — 56 ultrasound SKUs listed. RELEVANCE: do NOT pitch a competing console; four of their principals already sell one. What none of those four sells is a scanner at CHISON's price point, and Medical Space builds the equipment list for every clinic they open, so a cheap handheld raises their attach rate without touching their GE or Fujifilm margin. NOTE: their 'maker index' is a supplier list, not a peer-dealer list — several MFR rows on this tab came from correcting that mistake. | I11: Veterinary equipment dealer + animal-hospital opening, planning, construction and refurbishment; showroom; used-equipment trade. Line card includes GE HealthCare Japan, Canon Medtech Supply, Fujifilm/Fujifilm Medical, Konica Minolta, esaote veterinary, Nihon Kohden, Dräger, Olympus, IDEXX. | J11: YES — GE, Canon, Fujifilm and esaote veterinary; 56 ultrasound SKUs listed | K11: Nationwide; showroom | L11: https://medical-space.co.jp | M11: TEL 048-972-5890 · FAX 048-972-5891 | N11: No public address — form: medical-space.co.jp/contact/ | O11: 〒343-0037 埼玉県越谷市恩間新田228-1 (CEO 長谷川博彦) | P11: A — VERIFIED DIRECT (phone off company profile page) | Q11: Heavy cart-tier conflict, so do NOT pitch a competing console. Pitch the pocket tier none of their four ultrasound principals sells at CHISON's price. They build the equipment list for every new clinic they open — a low-cost handheld raises their attach rate without touching their GE/Fujifilm margin. NEW FACT: they already hold a FOREIGN MANUFACTURER registration for veterinary devices (動物用医療機器外国製造業 24外製療第300号) plus a Class-2 marketing authorisation and a repair licence — so the regulatory route for a foreign brand is already built. That materially raises their value despite the ultrasound conflict. | R11: SonoEye P3 / P5 VET only (pocket tier wedge) | S11: TIER 2 | T11: MEDIUM — heavy cart-tier conflict. Pocket tier only, but their new-clinic influence is real. | U11: B | V11: Verified — company profile page fetched 4 Aug 2026 | W11: Medical Space Inc.: not a replacement for your ultrasound line, the tier below it | X11: Dear 株式会社メディカルスペース (Medical Space Inc.) team, My name is Casper Tan, Senior Regional Sales Manager at AstraMed Healthcare, a subsidiary of CHISON Medical Technologies. I cover Japan, South Korea, Taiwan and Singapore for CHISON veterinary ultrasound. I am writing to Medical Space Inc. specifically, not to a list. You carry GE, Canon, Fujifilm and esaote veterinary, so I am not going to pretend I am writing about a console. I am writing because you also hold a foreign-manufacturer registration for veterinary devices and a Class-2 marketing authorisation, and because none of your four ultrasound principals builds the pocket tier. CHISON makes veterinary ultrasound across the range, but the part that should interest you is the handheld tier, SonoEye P3 and P5. Small, vet-preset, high-frequency linear for feline and exotic work, and priced where a GP clinic buys one outright or a hospital buys three as ward units. It sits under your existing line rather than against it. For context: we have no appointed veterinary distributor in Japan and would rather build one than sell around one. The product I would put in front of you first is the SonoEye P3 / P5 VET only (pocket tier wedge). Would twenty minutes be worth it, to see whether this protects your top-tier margin rather than competing with it? Best regards, Casper Tan Senior Regional Sales Manager AstraMed Healthcare, a subsidiary of CHISON Medical Technologies casper@astramed.sg | +65 8719 0121
A12: 8 | B12: 株式会社メディカルタスクフォース | C12: Medical Task Force Inc. (MTF) | D12: Not started | H12: Veterinary medical device company publishing an animal-device catalogue that covers ultrasound imaging and portable X-ray. RELEVANCE: they already understand the ultrasound sale and its service load, which shortens the learning curve — but it also means an incumbent line. The realistic opening is the sub-USD 10k handheld tier rather than a head-to-head console pitch. | I12: Veterinary medical devices; publishes an animal-device catalogue covering ultrasound imaging and portable X-ray. | J12: YES — carries ultrasound | K12: Japan | L12: medical-taskforce.com | M12: Corporate enquiry form | N12: NOT CONFIRMED | O12: Japan | P12: D — NOT VERIFIED (no contact record; confirm the company before contacting) | Q12: Already sells ultrasound into vet, so they understand the sale and the service load. Qualify which brand and at what price band before pitching; the opening is likely the sub-USD 10k handheld tier rather than their existing console line. | R12: SonoEye P3 VET; SonoAir 30 VET if their line is cart-only | S12: TIER 2 | T12: MEDIUM — already sells ultrasound, so qualify the brand and price band first. | U12: B | V12: Verified site (search-indexed) · v11 CHECK 27 Sep 2026: medical-taskforce.com did not resolve in DNS; the site may have moved or closed, confirm before relying on it. | W12: Medical Task Force Inc. (MTF): not a replacement for your ultrasound line, the tier below it | X12: Dear 株式会社メディカルタスクフォース (Medical Task Force Inc.) team, My name is Casper Tan, Senior Regional Sales Manager at AstraMed Healthcare, a subsidiary of CHISON Medical Technologies. I cover Japan, South Korea, Taiwan and Singapore for CHISON veterinary ultrasound. I am writing to Medical Task Force Inc. specifically, not to a list. You already publish an animal-device catalogue covering ultrasound imaging and portable X-ray, so you know how this product sells and what the service load looks like. The opening is the sub-console tier rather than anything you currently list. CHISON makes veterinary ultrasound across the range, but the part that should interest you is the handheld tier, SonoEye P3 and P5. Small, vet-preset, high-frequency linear for feline and exotic work, and priced where a GP clinic buys one outright or a hospital buys three as ward units. It sits under your existing line rather than against it. For context: we have no appointed veterinary distributor in Japan and would rather build one than sell around one. The product I would put in front of you first is the SonoEye P3 VET; SonoAir 30 VET if their line is cart-only. Would twenty minutes be worth it, to see whether this protects your top-tier margin rather than competing with it? Best regards, Casper Tan Senior Regional Sales Manager AstraMed Healthcare, a subsidiary of CHISON Medical Technologies casper@astramed.sg | +65 8719 0121
A13: 9 | B13: 株式会社東京メニックス | C13: Tokyo Menix Co., Ltd. | D13: Not started | H13: Long-standing manufacturer and supplier of small-animal medical devices, described in the trade as a leading company in the Japanese veterinary device field, with 65 SKUs moving through the Medical Space channel. RELEVANCE CORRECTION: confirmed on Medical Space's SUPPLIER list — they sell INTO dealers rather than alongside them. Real brand weight with Japanese vets, so worth a complementary-line or OEM conversation, but never treat this as a distribution appointment. | I13: Long-standing manufacturer/supplier of small-animal medical devices; described as a leading company in the Japanese vet device field. 65 SKUs listed through the Medical Space channel. | J13: Not identified | K13: Tokyo; national | L13: t-menix.com | M13: Corporate enquiry form | N13: NOT CONFIRMED | O13: Tokyo; national | P13: MFR — not a distribution target. Complementary-line / OEM talk only. | Q13: RELEVANCE CORRECTION (v3): Confirmed on the Medical Space supplier list — they SELL INTO dealers. Treat as a manufacturer, i.e. a possible complementary-line or OEM conversation, NOT a distributor to appoint. Manufacturer-plus-channel hybrid with genuine brand weight among Japanese vets. Best framed as a complementary-line agreement rather than pure distribution — their catalogue reaches clinics that a foreign brand cannot cold-call. | R13: SonoEye P3 VET + EBit 50 VET | S13: MFR | T13: MEDIUM — manufacturer, not a distributor. Complementary-line or OEM conversation only. | U13: MFR | V13: Verified site (search-indexed) | W13: Tokyo Menix Co., Ltd.: a complementary veterinary ultrasound line | X13: Dear 株式会社東京メニックス (Tokyo Menix Co., Ltd.) team, My name is Casper Tan, Senior Regional Sales Manager at AstraMed Healthcare, a subsidiary of CHISON Medical Technologies. I cover Japan, South Korea, Taiwan and Singapore for CHISON veterinary ultrasound. I am writing to Tokyo Menix Co., Ltd. specifically, not to a list. You are one of the established names in Japanese small-animal medical devices, and you sell into the dealer network rather than competing with it. CHISON manufactures veterinary ultrasound, handheld SonoEye, portable SonoGO and SonoAir, and cart systems, with vet presets and a full probe range. Rather than a distribution proposal, I am writing about whether a complementary-line or OEM arrangement would be of interest to you. For context: we have no appointed veterinary distributor in Japan and would rather build one than sell around one. The product I would put in front of you first is the SonoEye P3 VET and EBit 50 VET. Would a short call be worthwhile? Best regards, Casper Tan Senior Regional Sales Manager AstraMed Healthcare, a subsidiary of CHISON Medical Technologies casper@astramed.sg | +65 8719 0121
