Workbook

Sheet Read Me
A1: CHISON Ultrasound: Radiology and Vet Event Plan | Singapore, Taiwan, South Korea, Japan | Dec 2026 to Dec 2027
A2: Version 1, prepared 25 Oct 2026 for Casper Tan, Senior Regional Sales Manager and Manager KOL Engagement, AstraMed (CHISON Medical Technologies)
A4: WHAT THIS WORKBOOK DOES
A5: Objective | B5: Find radiology and vet events in Singapore, Taiwan, South Korea and Japan from Dec 2026 to Dec 2027 to recruit distributors, raise CHISON ultrasound publicity and support your KOL engagement.
A6: Tabs | B6: Coverage Summary (counts versus your targets, live formulas) | Next 60 Days (events starting soon, live Days Left) | Diagnostics Events | Vet Events | Competitor and Dealer Intel.
A7: Competitor columns | B7: Each event row shows which competitors (SonoScape, Mindray, Samsung, Philips, GE and others) are present or expected, and how strong the evidence is. Local dealers of competitors are listed where found.
A8: Format notes | B8: Dates are real Excel dates where the organiser has published them. TBC rows show only the month pattern from the last edition. No future date has been invented.
A10: THE THREE EVENTS TO COMMIT TO FIRST
A11: 1. JRC 2027 with ITEM 2027 (Japan, imaging) | B11: 15 to 18 Apr 2027, Pacifico Yokohama. Japan's biggest imaging floor and radiology KOL meeting in one place (ITEM 2026: 153 exhibitors, 18,180 visitors). Siemens, Canon, Fujifilm and GE were seen at recent editions. Cost: not published (JIRA sets terms). Deadline: ITEM exhibitor window not found, so ask JIRA by end of November.
A12: 2. KIMES 2027 (Korea, dealers) | B12: 18 to 21 Mar 2027, COEX Seoul. Korea's #1 medtech show and the best floor for importer and dealer recruitment. Samsung Medison and GE HealthCare were confirmed at KIMES 2026. Cost: not published. Deadline: booth form not published, so ask Korea E and Ex in November for the early bird rate.
A13: 3. JCVIM 2027 (Japan, vet) | B13: 19 to 21 Feb 2027, Pacifico Yokohama North. The only vet event on this list with a documented sponsorship path (sponsor recruitment opened 7 Jul 2026). Fujifilm VET Systems exhibited at the last three editions. Cost: tiers on smartconf.jp, fees not retrieved. Deadline: closing date not stated, so assume it is close and ask this month.
A15: COUNTRY ANCHOR EVENTS
A16: Singapore | B16: SGCR WIRES 2027 with the 14th Asian Congress of Abdominal Radiology, 19 to 22 Aug 2027 (venue to be announced). Vet: confirm Singapore Vet Show dates with CloserStill.
A17: Taiwan | B17: Visit Healthcare+ Expo Taiwan 3 to 6 Dec 2026 as a buyer, then target SUMROC 2027 and TAOG 2027 (both TBC). Vet: AiCVS and AiCVIM Joint Congress, Kaohsiung, 12 to 13 Dec 2026.
A18: South Korea | B18: KIMES 2027 (18 to 21 Mar), KSUM 2027 (May, TBC), KCR 2027 (22 to 25 Sep). Vet: 24th KAHA Conference, COEX Magok, 4 to 6 Jun 2027. Samsung Medison has a training partnership with KAHA.
A19: Japan | B19: JRC and ITEM (15 to 18 Apr), JSUM 100th (28 to 30 May), JSS 52nd (19 to 20 Jun), Medical Japan Osaka (29 Sep to 1 Oct). Vet: JCVIM (Feb), WJVF (31 Jul to 1 Aug), JBVP Annual (25 to 26 Sep).
A21: DO THIS IN THE NEXT 30 DAYS
A22: 1 | B22: Korea vet: ask KVECCS for a scanner slot in the POCUS practical at its seminar on 4 to 6 Dec 2026.
A23: 2 | B23: Korea: ask the Korean Association of Clinical Ultrasound about lending scanners to the ISCU 2026 Hands On School, 5 to 6 Dec 2026, COEX Magok.
A24: 3 | B24: Taiwan vet: contact the AiCVS and AiCVIM organisers (aicvs-aicvim2026.tw) about sponsor or imaging session space, event on 12 to 13 Dec 2026 in Kaohsiung.
A25: 4 | B25: Japan vet: ask the JSVDI secretariat if exhibit space remains for 5 to 6 Dec 2026, Fukuoka.
A26: 5 | B26: Taiwan: plan one Kaohsiung trip for 11 to 14 Dec 2026 (Chanchao Pets Show plus AiCVS and AiCVIM), and Taipei for Healthcare+ Expo on 3 to 6 Dec 2026.
A27: 6 | B27: Japan vet: open smartconf.jp/content/jcvim2027/sponsorship and request the sponsor tier list.
A28: 7 | B28: Request 2027 exhibitor guides and prices from: JIRA (ITEM), Korea E and Ex (KIMES), JSUM secretariat, JSS secretariat, CloserStill (Singapore Vet Show), SUMROC, TAOG, KAHA.
A29: 8 | B29: If your diary allows, SUMROC 2026 runs 31 Oct to 1 Nov in Taipei (6 days away, before the window). GE HealthCare Ultrasound, Alpinion and Rotary (Canon agent) support it.
A31: COMPETITOR HEADLINES
A32: Samsung in Korea vet | B32: Samsung Medison signed an MoU with the Korean Animal Hospital Association (KAHA) in Feb 2026 to build a nationwide Samsung Sono VET Academy ultrasound training network, including a KAHA STARTER basic ultrasound course. Expect a strong Samsung presence at KAHA events. The MoU names no event, so attendance at a specific event is not confirmed.
A33: Fujifilm in Japan | B33: Fujifilm (including Fujifilm VET Systems) is the benchmark: luncheon seminar at JSUM 2026, booth at ITEM 2026, exhibition and luncheon seminars at JCVIM 2024 to 2026 and JBVP 2025.
A34: Japan vet dealers | B34: Shoei Japan is the Japan importer for SonoScape vet models (S6V, A6V, X5V, E2V) and Mindray 6600vet. Mediark, Canon Medtech Supply and Frontier International (livestock) also sell vet ultrasound.
A35: Taiwan vet dealers | B35: Uni Soar (GE vet series), Soarmed (VINNO), Eastech (Esaote) and Getech (Philips cardiac) carry other brands, per their websites. No Taiwan vet distributor for Mindray, Samsung or SonoScape was found.
A36: Taiwan human ultrasound | B36: The SUMROC 2026 annual meeting page shows GE HealthCare Ultrasound, Alpinion and Rotary Trading (Canon Medical agent) logos. ASUS and Daikso showed handheld ultrasound at Healthcare+ Expo 2025.
A37: Korea human ultrasound | B37: KIMES 2026: Samsung Medison and GE HealthCare booths confirmed. KSUM 2026: Canon Medical Korea ran a luncheon symposium. KCR 2026: GE HealthCare ran a luncheon symposium.
A38: Mindray and SonoScape | B38: No public evidence was found of either company exhibiting at the human ultrasound congresses checked in the four markets. Absence in search results is not proof, so check each organiser's exhibitor list.
A40: HOW TO READ THE EVENT TABS
A41: Priority | B41: P1 = must attend: top KOL congress or #1 trade show for the market, with an open vendor path or competitors present. P2 = strong value for a specific specialty. P3 = optional, attend if already in town or a deal requires it.
A42: Segment | B42: Diagnostics (blue), Vet (green), Both (yellow). Both marks general medtech shows where vet distributors also walk the floor. They appear on both tabs and are counted on both.
A43: Date Class | B43: Confirmed = the organiser's own page shows the date (the venue may still be pending). Provisional = a media report or single third party source, an organiser page I could not read directly, conflicting sources, or an unclear listing. TBC = the organiser has not published 2027, and the row shows the last edition's pattern only.
A44: Competitor Evidence | B44: Confirmed = a press release, organiser page or sponsor logo was found for that edition. Partly confirmed = some brands confirmed, others not. Likely = normal for this type of event but not seen. Unverified = no information, and the competitor column then starts with Expected, not verified. Gap (Competitor and Dealer Intel tab only) = searched and nothing found.
A45: KOL and Dealer potential | B45: High, Medium or Low is my judgement of realistic payoff for CHISON, not the prestige of the event.
A46: Cost Info | B46: Exhibitor prices are almost never published. Where blank, request the exhibitor guide from the organiser.
...

Sheet Coverage Summary
A1: Coverage against your target (live formulas, they update when you edit the event tabs)
A3: Diagnostics and radiology events (sheet: Diagnostics Events)
A4: Country | B4: Target | C4: Listed | D4: Clinical or specialist events only (excl. general shows and pet shows) | E4: General medtech shows (Both) | F4: Pet industry shows | G4: Date Confirmed | H4: Date Provisional (verify) | I4: Date TBC (annual pattern) | J4: P1 | K4: P2 | L4: P3 | M4: Worth a trip (P1 plus P2) | N4: Meets target?
A5: Singapore | B5: 10 | C5: =COUNTIFS('Diagnostics Events'!$D$3:$D$400,A5) -> 13 | D5: =COUNTIFS('Diagnostics Events'!$D$3:$D$400,A5,'Diagnostics Events'!$C$3:$C$400,"Diagnostics",'Diagnostics Events'!$M$3:$M$400,"<>*Pet*") -> 13 | E5: =COUNTIFS('Diagnostics Events'!$D$3:$D$400,A5,'Diagnostics Events'!$C$3:$C$400,"Both") -> 0 | F5: =COUNTIFS('Diagnostics Events'!$D$3:$D$400,A5,'Diagnostics Events'!$M$3:$M$400,"*Pet*") -> 0 | G5: =COUNTIFS('Diagnostics Events'!$D$3:$D$400,A5,'Diagnostics Events'!$J$3:$J$400,"Confirmed") -> 5 | H5: =COUNTIFS('Diagnostics Events'!$D$3:$D$400,A5,'Diagnostics Events'!$J$3:$J$400,"Provisional") -> 7 | I5: =COUNTIFS('Diagnostics Events'!$D$3:$D$400,A5,'Diagnostics Events'!$J$3:$J$400,"TBC") -> 1 | J5: =COUNTIFS('Diagnostics Events'!$D$3:$D$400,A5,'Diagnostics Events'!$B$3:$B$400,"P1") -> 2 | K5: =COUNTIFS('Diagnostics Events'!$D$3:$D$400,A5,'Diagnostics Events'!$B$3:$B$400,"P2") -> 5 | L5: =COUNTIFS('Diagnostics Events'!$D$3:$D$400,A5,'Diagnostics Events'!$B$3:$B$400,"P3") -> 6 | M5: =J5+K5 -> 7 | N5: =IF(C5>=B5,"Yes","SHORT by "&(B5-C5)) -> Yes
A6: Taiwan | B6: 10 | C6: =COUNTIFS('Diagnostics Events'!$D$3:$D$400,A6) -> 12 | D6: =COUNTIFS('Diagnostics Events'!$D$3:$D$400,A6,'Diagnostics Events'!$C$3:$C$400,"Diagnostics",'Diagnostics Events'!$M$3:$M$400,"<>*Pet*") -> 9 | E6: =COUNTIFS('Diagnostics Events'!$D$3:$D$400,A6,'Diagnostics Events'!$C$3:$C$400,"Both") -> 3 | F6: =COUNTIFS('Diagnostics Events'!$D$3:$D$400,A6,'Diagnostics Events'!$M$3:$M$400,"*Pet*") -> 0 | G6: =COUNTIFS('Diagnostics Events'!$D$3:$D$400,A6,'Diagnostics Events'!$J$3:$J$400,"Confirmed") -> 3 | H6: =COUNTIFS('Diagnostics Events'!$D$3:$D$400,A6,'Diagnostics Events'!$J$3:$J$400,"Provisional") -> 1 | I6: =COUNTIFS('Diagnostics Events'!$D$3:$D$400,A6,'Diagnostics Events'!$J$3:$J$400,"TBC") -> 8 | J6: =COUNTIFS('Diagnostics Events'!$D$3:$D$400,A6,'Diagnostics Events'!$B$3:$B$400,"P1") -> 3 | K6: =COUNTIFS('Diagnostics Events'!$D$3:$D$400,A6,'Diagnostics Events'!$B$3:$B$400,"P2") -> 9 | L6: =COUNTIFS('Diagnostics Events'!$D$3:$D$400,A6,'Diagnostics Events'!$B$3:$B$400,"P3") -> 0 | M6: =J6+K6 -> 12 | N6: =IF(C6>=B6,"Yes","SHORT by "&(B6-C6)) -> Yes
A7: South Korea | B7: 10 | C7: =COUNTIFS('Diagnostics Events'!$D$3:$D$400,A7) -> 13 | D7: =COUNTIFS('Diagnostics Events'!$D$3:$D$400,A7,'Diagnostics Events'!$C$3:$C$400,"Diagnostics",'Diagnostics Events'!$M$3:$M$400,"<>*Pet*") -> 12 | E7: =COUNTIFS('Diagnostics Events'!$D$3:$D$400,A7,'Diagnostics Events'!$C$3:$C$400,"Both") -> 1 | F7: =COUNTIFS('Diagnostics Events'!$D$3:$D$400,A7,'Diagnostics Events'!$M$3:$M$400,"*Pet*") -> 0 | G7: =COUNTIFS('Diagnostics Events'!$D$3:$D$400,A7,'Diagnostics Events'!$J$3:$J$400,"Confirmed") -> 4 | H7: =COUNTIFS('Diagnostics Events'!$D$3:$D$400,A7,'Diagnostics Events'!$J$3:$J$400,"Provisional") -> 1 | I7: =COUNTIFS('Diagnostics Events'!$D$3:$D$400,A7,'Diagnostics Events'!$J$3:$J$400,"TBC") -> 8 | J7: =COUNTIFS('Diagnostics Events'!$D$3:$D$400,A7,'Diagnostics Events'!$B$3:$B$400,"P1") -> 3 | K7: =COUNTIFS('Diagnostics Events'!$D$3:$D$400,A7,'Diagnostics Events'!$B$3:$B$400,"P2") -> 8 | L7: =COUNTIFS('Diagnostics Events'!$D$3:$D$400,A7,'Diagnostics Events'!$B$3:$B$400,"P3") -> 2 | M7: =J7+K7 -> 11 | N7: =IF(C7>=B7,"Yes","SHORT by "&(B7-C7)) -> Yes
A8: Japan | B8: 20 | C8: =COUNTIFS('Diagnostics Events'!$D$3:$D$400,A8) -> 23 | D8: =COUNTIFS('Diagnostics Events'!$D$3:$D$400,A8,'Diagnostics Events'!$C$3:$C$400,"Diagnostics",'Diagnostics Events'!$M$3:$M$400,"<>*Pet*") -> 21 | E8: =COUNTIFS('Diagnostics Events'!$D$3:$D$400,A8,'Diagnostics Events'!$C$3:$C$400,"Both") -> 2 | F8: =COUNTIFS('Diagnostics Events'!$D$3:$D$400,A8,'Diagnostics Events'!$M$3:$M$400,"*Pet*") -> 0 | G8: =COUNTIFS('Diagnostics Events'!$D$3:$D$400,A8,'Diagnostics Events'!$J$3:$J$400,"Confirmed") -> 19 | H8: =COUNTIFS('Diagnostics Events'!$D$3:$D$400,A8,'Diagnostics Events'!$J$3:$J$400,"Provisional") -> 1 | I8: =COUNTIFS('Diagnostics Events'!$D$3:$D$400,A8,'Diagnostics Events'!$J$3:$J$400,"TBC") -> 3 | J8: =COUNTIFS('Diagnostics Events'!$D$3:$D$400,A8,'Diagnostics Events'!$B$3:$B$400,"P1") -> 4 | K8: =COUNTIFS('Diagnostics Events'!$D$3:$D$400,A8,'Diagnostics Events'!$B$3:$B$400,"P2") -> 13 | L8: =COUNTIFS('Diagnostics Events'!$D$3:$D$400,A8,'Diagnostics Events'!$B$3:$B$400,"P3") -> 6 | M8: =J8+K8 -> 17 | N8: =IF(C8>=B8,"Yes","SHORT by "&(B8-C8)) -> Yes
A9: Total | B9: =SUM(B5:B8) -> 50 | C9: =SUM(C5:C8) -> 61 | D9: =SUM(D5:D8) -> 55 | E9: =SUM(E5:E8) -> 6 | F9: =SUM(F5:F8) -> 0 | G9: =SUM(G5:G8) -> 31 | H9: =SUM(H5:H8) -> 10 | I9: =SUM(I5:I8) -> 20 | ... M9: =SUM(M5:M8) -> 47 | N9: =IF(COUNTIF(N5:N8,"Yes")=4,"Yes","SHORT in "&(4-COUNTIF(N5:N8,"Yes"))&" market(s)") -> Yes
A12: Vet events (sheet: Vet Events)
A13: Country | B13: Target | C13: Listed | D13: Clinical or specialist events only (excl. general shows and pet shows) | E13: General medtech shows (Both) | F13: Pet industry shows | G13: Date Confirmed | H13: Date Provisional (verify) | I13: Date TBC (annual pattern) | J13: P1 | K13: P2 | L13: P3 | M13: Worth a trip (P1 plus P2) | N13: Meets target?
A14: Singapore | B14: 10 | C14: =COUNTIFS('Vet Events'!$D$3:$D$400,A14) -> 7 | D14: =COUNTIFS('Vet Events'!$D$3:$D$400,A14,'Vet Events'!$C$3:$C$400,"Vet",'Vet Events'!$M$3:$M$400,"<>*Pet*") -> 5 | E14: =COUNTIFS('Vet Events'!$D$3:$D$400,A14,'Vet Events'!$C$3:$C$400,"Both") -> 0 | F14: =COUNTIFS('Vet Events'!$D$3:$D$400,A14,'Vet Events'!$M$3:$M$400,"*Pet*") -> 2 | G14: =COUNTIFS('Vet Events'!$D$3:$D$400,A14,'Vet Events'!$J$3:$J$400,"Confirmed") -> 0 | H14: =COUNTIFS('Vet Events'!$D$3:$D$400,A14,'Vet Events'!$J$3:$J$400,"Provisional") -> 2 | I14: =COUNTIFS('Vet Events'!$D$3:$D$400,A14,'Vet Events'!$J$3:$J$400,"TBC") -> 5 | J14: =COUNTIFS('Vet Events'!$D$3:$D$400,A14,'Vet Events'!$B$3:$B$400,"P1") -> 1 | K14: =COUNTIFS('Vet Events'!$D$3:$D$400,A14,'Vet Events'!$B$3:$B$400,"P2") -> 4 | L14: =COUNTIFS('Vet Events'!$D$3:$D$400,A14,'Vet Events'!$B$3:$B$400,"P3") -> 2 | M14: =J14+K14 -> 5 | N14: =IF(C14>=B14,"Yes","SHORT by "&(B14-C14)) -> SHORT by 3
A15: Taiwan | B15: 10 | C15: =COUNTIFS('Vet Events'!$D$3:$D$400,A15) -> 11 | D15: =COUNTIFS('Vet Events'!$D$3:$D$400,A15,'Vet Events'!$C$3:$C$400,"Vet",'Vet Events'!$M$3:$M$400,"<>*Pet*") -> 4 | E15: =COUNTIFS('Vet Events'!$D$3:$D$400,A15,'Vet Events'!$C$3:$C$400,"Both") -> 2 | F15: =COUNTIFS('Vet Events'!$D$3:$D$400,A15,'Vet Events'!$M$3:$M$400,"*Pet*") -> 5 | G15: =COUNTIFS('Vet Events'!$D$3:$D$400,A15,'Vet Events'!$J$3:$J$400,"Confirmed") -> 4 | H15: =COUNTIFS('Vet Events'!$D$3:$D$400,A15,'Vet Events'!$J$3:$J$400,"Provisional") -> 1 | I15: =COUNTIFS('Vet Events'!$D$3:$D$400,A15,'Vet Events'!$J$3:$J$400,"TBC") -> 6 | J15: =COUNTIFS('Vet Events'!$D$3:$D$400,A15,'Vet Events'!$B$3:$B$400,"P1") -> 1 | K15: =COUNTIFS('Vet Events'!$D$3:$D$400,A15,'Vet Events'!$B$3:$B$400,"P2") -> 4 | L15: =COUNTIFS('Vet Events'!$D$3:$D$400,A15,'Vet Events'!$B$3:$B$400,"P3") -> 6 | M15: =J15+K15 -> 5 | N15: =IF(C15>=B15,"Yes","SHORT by "&(B15-C15)) -> Yes
A16: South Korea | B16: 10 | C16: =COUNTIFS('Vet Events'!$D$3:$D$400,A16) -> 12 | D16: =COUNTIFS('Vet Events'!$D$3:$D$400,A16,'Vet Events'!$C$3:$C$400,"Vet",'Vet Events'!$M$3:$M$400,"<>*Pet*") -> 9 | E16: =COUNTIFS('Vet Events'!$D$3:$D$400,A16,'Vet Events'!$C$3:$C$400,"Both") -> 1 | F16: =COUNTIFS('Vet Events'!$D$3:$D$400,A16,'Vet Events'!$M$3:$M$400,"*Pet*") -> 2 | G16: =COUNTIFS('Vet Events'!$D$3:$D$400,A16,'Vet Events'!$J$3:$J$400,"Confirmed") -> 0 | H16: =COUNTIFS('Vet Events'!$D$3:$D$400,A16,'Vet Events'!$J$3:$J$400,"Provisional") -> 3 | I16: =COUNTIFS('Vet Events'!$D$3:$D$400,A16,'Vet Events'!$J$3:$J$400,"TBC") -> 9 | J16: =COUNTIFS('Vet Events'!$D$3:$D$400,A16,'Vet Events'!$B$3:$B$400,"P1") -> 2 | K16: =COUNTIFS('Vet Events'!$D$3:$D$400,A16,'Vet Events'!$B$3:$B$400,"P2") -> 5 | L16: =COUNTIFS('Vet Events'!$D$3:$D$400,A16,'Vet Events'!$B$3:$B$400,"P3") -> 5 | M16: =J16+K16 -> 7 | N16: =IF(C16>=B16,"Yes","SHORT by "&(B16-C16)) -> Yes
A17: Japan | B17: 20 | C17: =COUNTIFS('Vet Events'!$D$3:$D$400,A17) -> 23 | D17: =COUNTIFS('Vet Events'!$D$3:$D$400,A17,'Vet Events'!$C$3:$C$400,"Vet",'Vet Events'!$M$3:$M$400,"<>*Pet*") -> 19 | E17: =COUNTIFS('Vet Events'!$D$3:$D$400,A17,'Vet Events'!$C$3:$C$400,"Both") -> 2 | F17: =COUNTIFS('Vet Events'!$D$3:$D$400,A17,'Vet Events'!$M$3:$M$400,"*Pet*") -> 2 | G17: =COUNTIFS('Vet Events'!$D$3:$D$400,A17,'Vet Events'!$J$3:$J$400,"Confirmed") -> 16 | H17: =COUNTIFS('Vet Events'!$D$3:$D$400,A17,'Vet Events'!$J$3:$J$400,"Provisional") -> 0 | I17: =COUNTIFS('Vet Events'!$D$3:$D$400,A17,'Vet Events'!$J$3:$J$400,"TBC") -> 7 | J17: =COUNTIFS('Vet Events'!$D$3:$D$400,A17,'Vet Events'!$B$3:$B$400,"P1") -> 4 | K17: =COUNTIFS('Vet Events'!$D$3:$D$400,A17,'Vet Events'!$B$3:$B$400,"P2") -> 8 | L17: =COUNTIFS('Vet Events'!$D$3:$D$400,A17,'Vet Events'!$B$3:$B$400,"P3") -> 11 | M17: =J17+K17 -> 12 | N17: =IF(C17>=B17,"Yes","SHORT by "&(B17-C17)) -> Yes
A18: Total | B18: =SUM(B14:B17) -> 50 | C18: =SUM(C14:C17) -> 53 | D18: =SUM(D14:D17) -> 37 | E18: =SUM(E14:E17) -> 5 | F18: =SUM(F14:F17) -> 11 | G18: =SUM(G14:G17) -> 20 | H18: =SUM(H14:H17) -> 6 | I18: =SUM(I14:I17) -> 27 | ... M18: =SUM(M14:M17) -> 29 | N18: =IF(COUNTIF(N14:N17,"Yes")=4,"Yes","SHORT in "&(4-COUNTIF(N14:N17,"Yes"))&" market(s)") -> SHORT in 1 market(s)
A20: Blue numbers in the Target column are your targets (10 per country, 20 for Japan). Edit them if the target changes.
A21: Listed counts every row on the tab, including P3 optional events. General medtech shows (Segment = Both) are on both tabs because vet distributors walk medtech floors. Consumer pet shows are counted as vet events only to reach your target, so read the clinical only column and the P1 plus P2 column for the real number worth a trip.
A22: Date Confirmed means the organiser's own page shows the date. Provisional means a single or conflicting source. TBC means the organiser has not published 2027 yet, and the row shows the annual pattern only. No future date has been invented.
A23: Singapore vet is SHORT of 10 because few genuine vet events exist in Singapore. Aggregator listings of generic Singapore vet symposia were checked and excluded as low credibility. See the Read Me for regional alternatives.

Sheet Next 60 Days
A1: EVENTS STARTING WITHIN 60 DAYS OF THE REFERENCE DATE. Contact organisers this week, because exhibitor windows for these have mostly closed or are closing.
A2: Reference date (edit) | B2: 46320 | C2: Change this date to re age the list. Days Left and Urgency recalculate (CRITICAL = 42 days or less, HIGH = 43 to 56, MEDIUM = more). Rows are events starting within 60 days of 25 Oct 2026.
A3: Start Date | B3: Days Left | C3: Urgency | D3: Priority | E3: Segment | F3: Country | G3: Event | H3: Dates | I3: City and Venue | J3: Deadline or Action | K3: Source
A4: 46359 | B4: =A4-$B$2 -> 39 | C4: =IF(B4<0,"PASSED",IF(B4<=42,"CRITICAL",IF(B4<=56,"HIGH","MEDIUM"))) -> CRITICAL | D4: P1 | E4: Both | F4: Taiwan | G4: Healthcare+ Expo Taiwan 2026 | H4: 3 to 6 Dec 2026 | I4: Taipei Nangang Exhibition Center Hall 1 (1F and 4F), Taipei | J4: Exhibitor sales for 2026 probably closed. Confirm with the organiser. Attend as a visitor. Walk the ultrasound and imaging aisles and collect importer cards. Nearest event on this list. | K4: https://expo.taiwan-healthcare.org/en/
A5: 46360 | B5: =A5-$B$2 -> 40 | C5: =IF(B5<0,"PASSED",IF(B5<=42,"CRITICAL",IF(B5<=56,"HIGH","MEDIUM"))) -> CRITICAL | D5: P1 | E5: Vet | F5: South Korea | G5: KVECCS Academic Seminar with RECOVER workshop and POCUS ultrasound practice (Korean Veterinary Emergency and Critical Care Society) | H5: 4 to 6 Dec 2026 | I5: Seoul (venue to be confirmed) | J5: Event is 6 weeks away. Ask the society now for a scanner loan slot. Contact KVECCS this week: offer 3 to 4 scanners for the POCUS practical session. | K5: https://www.dailyvet.co.kr/news/academy
A6: 46361 | B6: =A6-$B$2 -> 41 | C6: =IF(B6<0,"PASSED",IF(B6<=42,"CRITICAL",IF(B6<=56,"HIGH","MEDIUM"))) -> CRITICAL | D6: P2 | E6: Diagnostics | F6: South Korea | G6: KSE 2026, 61st Korean Society of Echocardiography Autumn Meeting | H6: 5 to 6 Dec 2026 | I6: Grand Walkerhill Seoul, Seoul | J6: Event is 6 weeks away. Ask the society office now. Ask for visitor access. Note names of the hands on session faculty. | K6: https://www.ksecho.org/academic_event/annual_schedule_all.php
A7: 46361 | B7: =A7-$B$2 -> 41 | C7: =IF(B7<0,"PASSED",IF(B7<=42,"CRITICAL",IF(B7<=56,"HIGH","MEDIUM"))) -> CRITICAL | D7: P2 | E7: Diagnostics | F7: South Korea | G7: ISCU 2026 and 29th Regular Meeting of the Korean Association of Clinical Ultrasound, with Hands On School | H7: 5 to 6 Dec 2026 | I7: COEX Magok, Seoul | J7: Abstract deadline 30 Oct 2026 (not relevant for vendors). Sponsor terms not found, event is 6 weeks away. Contact KACU this week to ask about equipment loan for the hands on school. | K7: https://iscu.or.kr/
A8: 46361 | B8: =A8-$B$2 -> 41 | C8: =IF(B8<0,"PASSED",IF(B8<=42,"CRITICAL",IF(B8<=56,"HIGH","MEDIUM"))) -> CRITICAL | D8: P2 | E8: Vet | F8: Japan | G8: JSVDI 79th Japanese Society of Veterinary Diagnostic Imaging Meeting | H8: 5 to 6 Dec 2026 | I8: Fukuoka International Congress Center, Fukuoka | J8: Event is 6 weeks away. Ask the secretariat now for any remaining exhibit space. Request an exhibit slot or visit to meet imaging KOLs. Plan the June 2027 meeting as the booth event. | K8: https://jsvdi.com/conference/3332/
A9: 46367 | B9: =A9-$B$2 -> 47 | C9: =IF(B9<0,"PASSED",IF(B9<=42,"CRITICAL",IF(B9<=56,"HIGH","MEDIUM"))) -> HIGH | D9: P3 | E9: Vet | F9: Taiwan | G9: Chanchao Kaohsiung Pets Show, December 2026 edition | H9: 11 to 14 Dec 2026 | I9: Kaohsiung Exhibition Center, Kaohsiung | J9: Closed for exhibitors. Optional. Walk it on 12 Dec if attending AiCVS. | K9: https://www.chanchao.com.tw/PetsShow/kaohsiung/
A10: 46368 | B10: =A10-$B$2 -> 48 | C10: =IF(B10<0,"PASSED",IF(B10<=42,"CRITICAL",IF(B10<=56,"HIGH","MEDIUM"))) -> HIGH | D10: P2 | E10: Diagnostics | F10: Taiwan | G10: TSOC Winter Scientific Meeting 2026 (Taiwan Society of Cardiology) | H10: 12 to 13 Dec 2026 | I10: Taipei International Convention Center (TICC), Taipei | J10: Not published. Event is 7 weeks away. Optional. Attend only if combined with Healthcare+ Expo trip. | K10: https://tsocmeeting.org/
A11: 46368 | B11: =A11-$B$2 -> 48 | C11: =IF(B11<0,"PASSED",IF(B11<=42,"CRITICAL",IF(B11<=56,"HIGH","MEDIUM"))) -> HIGH | D11: P2 | E11: Diagnostics | F11: Japan | G11: JSUM Kansai 53rd Regional Meeting and 30th Regional Seminar | H11: 12 Dec 2026 | I11: Osaka International Convention Center, Osaka | J11: Corporate exhibition terms not found. Event is 7 weeks away, so ask the secretariat this week. Email the secretariat for the exhibitor form. If closed, attend as a visitor and map Kansai KOLs and dealers. | K11: https://www.jsum.or.jp/members/calendar/2026/
A12: 46368 | B12: =A12-$B$2 -> 48 | C12: =IF(B12<0,"PASSED",IF(B12<=42,"CRITICAL",IF(B12<=56,"HIGH","MEDIUM"))) -> HIGH | D12: P1 | E12: Vet | F12: Taiwan | G12: AiCVS and AiCVIM Joint Congress 2026 (Asian veterinary surgery and internal medicine colleges) | H12: 12 to 13 Dec 2026 | I12: Kaohsiung Exhibition Center, Kaohsiung (venue per host association pages, the congress site names no venue) | J12: Event is 7 weeks away. Sponsor and exhibitor slots may still be open. Email the organiser (aicvs-aicvim2026.tw) this week. Offer a scanner for the imaging session. | K12: https://www.aicvs-aicvim2026.tw/
A13: 46372 | B13: =A13-$B$2 -> 52 | C13: =IF(B13<0,"PASSED",IF(B13<=42,"CRITICAL",IF(B13<=56,"HIGH","MEDIUM"))) -> HIGH | D13: P3 | E13: Vet | F13: Japan | G13: Skyvets abdominal ultrasound hands on seminar series (monthly, third Wednesday) | H13: 16 Dec 2026, 20 Jan, 17 Feb, 17 Mar 2027 | I13: Not stated (online imaging service with hands on) | J13: Registration per session. Ask Skyvets which scanners are used. | K13: https://sky-vets.com/seminar/
A14: 46374 | B14: =A14-$B$2 -> 54 | C14: =IF(B14<0,"PASSED",IF(B14<=42,"CRITICAL",IF(B14<=56,"HIGH","MEDIUM"))) -> HIGH | D14: P2 | E14: Vet | F14: Japan | G14: JSVAS 113th Japanese Society of Veterinary Anesthesia and Surgery Meeting | H14: 18 to 20 Dec 2026 | I14: Congress Square Grand Green Osaka, Osaka | J14: Event is 8 weeks away. Ask the secretariat now. Visit or exhibit if a Kansai vet dealer partner is in place. | K14: https://www.jsvas.net/conference/index.php

Sheet Diagnostics Events
A1: CHISON Ultrasound Diagnostics Event Plan | Singapore, Taiwan, South Korea, Japan | Dec 2026 to Dec 2027 | v1, prepared 25 Oct 2026
A2: # | B2: Priority | C2: Segment | D2: Country | E2: Event Name | F2: Start Date | G2: End Date | H2: Month (for sorting) | I2: Date as Published or Expected | J2: Date Class | K2: Date Status and Source Note | L2: City and Venue | M2: Type | N2: Field or Specialty | O2: Why It Matters for CHISON (product angle) | P2: Competitors Present or Expected | Q2: Competitor Evidence | R2: Local Dealers and Distributors to Meet | S2: KOL Potential | T2: Dealer Potential | U2: Scale or Attendance | V2: Cost Info (published) | W2: Deadlines That Bite | X2: Recommended Action | Y2: Source
A3: 1 | B3: P3 | C3: Diagnostics | D3: Singapore | E3: Singapore LIVE 2027 (National Heart Centre Singapore) | F3: 46415 | G3: 46417 | H3: 46388 | I3: 28 to 30 Jan 2027 | J3: Confirmed | K3: Confirmed per organiser page | L3: Singapore (venue not stated) | M3: Live case course | N3: Interventional cardiology, imaging | O3: Cardiology KOLs at NHCS. Interventional focus, so ultrasound relevance is limited. | P3: Expected, not verified: Philips, GE HealthCare, Abbott expected. | Q3: Unverified. Exhibitor list not published. | R3: Singapore distributors and regional ASEAN distributors who attend Singapore congresses. | S3: Medium | T3: Low | U3: Not published | V3: Not published. Request the exhibitor guide from the organiser. | W3: Not published. | X3: Optional. Contact NHCS only if a cardiology KOL is on the target list. | Y3: https://www.nhcs.com.sg/singlivecourse
A4: 2 | B4: P2 | C4: Diagnostics | D4: Singapore | E4: SSR 10th Annual Scientific Meeting (Singapore Society of Radiographers) | F4: 46479 | G4: 46480 | H4: 46478 | I4: 2 to 3 Apr 2027 | J4: Provisional | K4: Listed by the society. Location and theme to be confirmed | L4: Singapore (to be confirmed) | M4: Society annual meeting | N4: Radiography and sonography | O4: Radiographers and sonographers who evaluate ultrasound in public hospitals. | P4: Brands normally active in Singapore (market knowledge, not verified per event): Philips, GE HealthCare, Siemens Healthineers, Canon Medical, Samsung Medison, Mindray, SonoScape. No event specific exhibitor list found. | Q4: Unverified. Exhibitor list not published. | R4: Singapore distributors and regional ASEAN distributors who attend Singapore congresses. | S4: Medium | T4: Medium | U4: Not published | V4: Not published. Request the exhibitor guide from the organiser. | W4: Not published. Society page age looks stale, so verify. | X4: Email SSR to confirm the date and sponsor options. | Y4: https://www.ssr.org.sg/conference-list
A5: 3 | B5: P2 | C5: Diagnostics | D5: Singapore | E5: SingHealth Academy Basic POCUS Workshop, session 1 | F5: 46514 | G5: 46514 | H5: 46508 | I5: 7 May 2027 | J5: Provisional | K5: Provisional. Course page lists both sessions but its date format is unclear, verify | L5: Academia, 20 College Road, Singapore | M5: CME course | N5: Point of care ultrasound | O5: Residents in emergency, internal medicine and anaesthesia train here. Scanner supply for hands on is a practical opening for SonoEye and SonoAir. | P5: Training equipment supplier not stated. | Q5: Unverified. Exhibitor list not published. | R5: Singapore distributors and regional ASEAN distributors who attend Singapore congresses. | S5: High | T5: Low | U5: Small class | V5: Participant fee S$420 incl GST. | W5: Registration closes before each session. | X5: Contact SingHealth Academy to ask who supplies the scanners and whether CHISON can lend units. | Y5: https://www.singhealthacademy.edu.sg/sims/events-programmes/academia/point-of-care-ultrasound
A6: 4 | B6: P2 | C6: Diagnostics | D6: Singapore | E6: NYSORA Regional Anesthesia Conference Singapore 2027 | F6: 46515 | G6: 46516 | H6: 46508 | I6: 8 to 9 May 2027 | J6: Confirmed | K6: Confirmed per organiser listing | L6: Singapore (venue not stated) | M6: Hands on conference | N6: Ultrasound guided regional anaesthesia | O6: Hands on ultrasound nerve block training. Handheld and portable ultrasound fit. Sponsor tables are common at NYSORA courses. | P6: Expected, not verified: Fujifilm Sonosite, GE HealthCare (Vscan), Butterfly typical at NYSORA events. Unverified for this event. | Q6: Unverified. Exhibitor list not published. | R6: Singapore distributors and regional ASEAN distributors who attend Singapore congresses. | S6: High | T6: Medium | U6: Hands on course, under 300 (est.) | V6: Not published. Request the exhibitor guide from the organiser. | W6: Not published. | X6: Ask NYSORA for the industry sponsor pack. A scanner loan for the workshop is the cheapest option. | Y6: https://nysora.com/event/conferences/regional-anesthesia-conference-singapore-2027/
A7: 5 | B7: P3 | C7: Diagnostics | D7: Singapore | E7: Asia Healthcare Week 2027 (IQPC) | F7: 46532 | G7: 46535 | H7: 46508 | I7: 25 to 28 May 2027 | J7: Provisional | K7: Listed by an aggregator | L7: Singapore (venue not found) | M7: Conference | N7: Hospital planning and care journey | O7: Hospital planners and administrators. Useful for contacts, light on ultrasound. | P7: Not documented. | Q7: Unverified. Exhibitor list not published. | R7: Singapore distributors and regional ASEAN distributors who attend Singapore congresses. | S7: Low | T7: Medium | U7: Not published | V7: Not published. Request the exhibitor guide from the organiser. | W7: Not published. | X7: Optional. | Y7: https://www.iqpc.com/events-asiahealthcareweek
A8: 6 | B8: P3 | C8: Diagnostics | D8: Singapore | E8: HealthTechX Asia 2027 (3rd edition) | F8: 46547 | G8: 46548 | H8: 46539 | I8: 9 to 10 Jun 2027 | J8: Provisional | K8: Listed on organiser and 10times pages | L8: Sands Expo and Convention Centre, Marina Bay Sands, Singapore | M8: Digital health trade show | N8: Health tech | O8: Digital health. AI ultrasound software partners rather than distributors. | P8: Not relevant for ultrasound OEMs. | Q8: Unverified. Exhibitor list not published. | R8: Singapore distributors and regional ASEAN distributors who attend Singapore congresses. | S8: Low | T8: Low | U8: Over 90 exhibitors (organiser) | V8: Not published. Request the exhibitor guide from the organiser. | W8: Not published. | X8: Skip unless AI partnerships are in scope. | Y8: https://www.healthtechx-asia.com/
A9: 7 | B9: P3 | C9: Diagnostics | D9: Singapore | E9: Smart Health Asia 2027 | F9: 46575 | G9: 46576 | H9: 46569 | I9: 7 to 8 Jul 2027 | J9: Provisional | K9: Listed by organiser (Messe Berlin Singapore) | L9: Sands Expo and Convention Centre, Singapore | M9: Digital health trade show | N9: Digital health | O9: Digital health; small imaging share. | P9: Not relevant for ultrasound OEMs. | Q9: Unverified. Exhibitor list not published. | R9: Singapore distributors and regional ASEAN distributors who attend Singapore congresses. | S9: Low | T9: Low | U9: 150+ exhibitors, 5,000+ visitors (organiser claim) | V9: Not published. Request the exhibitor guide from the organiser. | W9: Not published. | X9: Skip. | Y9: https://smarthealthasia.com/
A10: 8 | B10: P3 | C10: Diagnostics | D10: Singapore | E10: UROFAIR 2027 (Singapore Urological Association) | F10: 46583 | G10: 46585 | H10: 46569 | I10: 15 to 17 Jul 2027 | J10: Confirmed | K10: Confirmed per society page | L10: Grand Copthorne Waterfront Hotel, Singapore | M10: Society meeting with fair | N10: Urology | O10: Urology ultrasound (prostate, bladder). Small but easy to approach. | P10: Brands normally active in Singapore (market knowledge, not verified per event): Philips, GE HealthCare, Siemens Healthineers, Canon Medical, Samsung Medison, Mindray, SonoScape. No event specific exhibitor list found. | Q10: Unverified. Exhibitor list not published. | R10: Singapore distributors and regional ASEAN distributors who attend Singapore congresses. | S10: Medium | T10: Low | U10: Not published | V10: Not published. Request the exhibitor guide from the organiser. | W10: Not published. | X10: Optional. Ask SUA for the exhibitor prospectus. | Y10: https://sua.sg/urofair-2027/
A11: 9 | B11: P2 | C11: Diagnostics | D11: Singapore | E11: APICS 2027, Asia Pacific Intensive Care Symposium | F11: 46617 | G11: 46622 | H11: 46600 | I11: 18 to 23 Aug 2027 | J11: Provisional | K11: Provisional. Listed by an aggregator only. The six day span looks too long and overlaps SGCR week, so it is likely an aggregator error. Verify with the organiser | L11: Singapore EXPO (per listing) | M11: Regional symposium | N11: Critical care ultrasound | O11: ICU physicians use POCUS and echo daily. Handheld and portable systems fit. | P11: Expected, not verified: GE HealthCare, Philips, Fujifilm Sonosite typical. Unverified. | Q11: Unverified. Exhibitor list not published. | R11: Singapore distributors and regional ASEAN distributors who attend Singapore congresses. | S11: High | T11: Medium | U11: Not published | V11: Not published. Request the exhibitor guide from the organiser. | W11: Not published. | X11: Confirm dates with the organiser before planning. | Y11: https://conferencealerts.co.in/singapore/medicine-and-medical-science
A12: 10 | B12: P1 | C12: Diagnostics | D12: Singapore | E12: ACAR SGCR WIRES 2027 (Asian Congress of Abdominal Radiology with the Singapore Congress of Radiology and WIRES) | F12: 46618 | G12: 46621 | H12: 46600 | I12: 19 to 22 Aug 2027 | J12: Confirmed | K12: Dates confirmed on organiser site. Venue to be announced | L12: Singapore (venue not yet announced). The 2026 edition was at Singapore EXPO | M12: National and Asian congress | N12: Radiology, abdominal and interventional imaging | O12: Singapore's top radiology congress (35th meeting per the organiser welcome page), joined by the 14th Asian abdominal radiology congress. Regional KOLs come to Singapore, so one trip covers ASEAN and North Asia. Abdominal ultrasound and elastography are core topics. | P12: Brands normally active in Singapore (market knowledge, not verified per event): Philips, GE HealthCare, Siemens Healthineers, Canon Medical, Samsung Medison, Mindray, SonoScape. No event specific exhibitor list found. | Q12: Unverified. 2026 AOCR plus SGCR exhibitor list not retrieved. | R12: Singapore distributors and regional ASEAN distributors who attend Singapore congresses. | S12: High | T12: High | U12: Not published | V12: Not published. Request the exhibitor guide from the organiser. | W12: Exhibitor prospectus not published. Ask the secretariat from Jan 2027. | X12: Priority 1 in Singapore. Request the prospectus and plan a regional distributor meeting around it. | Y12: https://www.sgcr-wires.com/acar2027
A13: 11 | B13: P2 | C13: Diagnostics | D13: Singapore | E13: SingHealth Academy Basic POCUS Workshop, session 2 | F13: 46640 | G13: 46640 | H13: 46631 | I13: 10 Sep 2027 | J13: Provisional | K13: Provisional. Course page lists both sessions but its date format is unclear, verify | L13: Academia, 20 College Road, Singapore | M13: CME course | N13: Point of care ultrasound | O13: Residents in emergency, internal medicine and anaesthesia train here. Scanner supply for hands on is a practical opening for SonoEye and SonoAir. | P13: Training equipment supplier not stated. | Q13: Unverified. Exhibitor list not published. | R13: Singapore distributors and regional ASEAN distributors who attend Singapore congresses. | S13: High | T13: Low | U13: Small class | V13: Participant fee S$420 incl GST. | W13: Registration closes before each session. | X13: Contact SingHealth Academy to ask who supplies the scanners and whether CHISON can lend units. | Y13: https://www.singhealthacademy.edu.sg/sims/events-programmes/academia/point-of-care-ultrasound
A14: 12 | B14: P3 | C14: Diagnostics | D14: Singapore | E14: IEEE International Ultrasonics Symposium 2027 | F14: 46642 | G14: 46645 | H14: 46631 | I14: 12 to 15 Sep 2027 | J14: Confirmed | K14: Confirmed per IEEE listing | L14: Singapore (venue not named) | M14: Engineering symposium | N14: Ultrasound physics and transducers | O14: Engineering audience. Awareness of competitor technology, not a sales event. | P14: Ultrasound OEM engineers. | Q14: Unverified. Exhibitor list not published. | R14: Not applicable. | S14: Low | T14: Low | U14: Not published | V14: Not published. Request the exhibitor guide from the organiser. | W14: Not published. | X14: Awareness only. | Y14: https://ieee-uffc.org/event/conference/2027-ieee-international-ultrasonics-symposium
A15: 13 | B15: P1 | C15: Diagnostics | D15: Singapore | E15: Singapore Health and Biomedical Congress (SHBC) 2027 | H15: 46661 | I15: Oct 2027 (not published) | J15: TBC | K15: TBC. Annual pattern: early October (2026: 8 to 9 Oct, 2025: 9 to 10 Oct at Singapore EXPO) | L15: Singapore EXPO (venue of recent editions) | M15: National healthcare congress with exhibition | N15: All specialties, public healthcare | O15: Largest multi specialty healthcare meeting in Singapore, run by NHG Health (National Healthcare Group) per its site. KOLs and procurement staff of public hospitals attend. | P15: Brands normally active in Singapore (market knowledge, not verified per event): Philips, GE HealthCare, Siemens Healthineers, Canon Medical, Samsung Medison, Mindray, SonoScape. No event specific exhibitor list found. | Q15: Unverified. Exhibitor list not published. | R15: Singapore distributors and regional ASEAN distributors who attend Singapore congresses. | S15: High | T15: High | U15: Not published | V15: Delegate day pass SGD 180 (2026). Exhibitor cost not published. | W15: Not published. | X15: Check shbc.com.sg after the 2026 edition for the 2027 call for exhibitors. | Y15: https://shbc.com.sg/
A16: 1 | B16: P1 | C16: Both | D16: Taiwan | E16: Healthcare+ Expo Taiwan 2026 | F16: 46359 | G16: 46362 | H16: 46357 | I16: 3 to 6 Dec 2026 | J16: Confirmed | K16: Confirmed | L16: Taipei Nangang Exhibition Center Hall 1 (1F and 4F), Taipei | M16: Trade exhibition | N16: Medical devices, smart hospital, digital health, precision medicine | O16: Taiwan's largest healthcare expo. Importers, hospital buyers and KOLs attend. The only large Taiwan show inside the first month of the window. | P16: Confirmed at the 2025 edition: ASUS (handheld ultrasound LU800 and EchoLab) and Daikso (portable ultrasound AI). Big five brands not found in the search. Official 2026 exhibitor list is on the expo site. | Q16: Partly confirmed. Large brand presence unverified. | R16: Rotary Trading (Canon Medical agent) is a known ultrasound dealer. Other Taiwan importers to scout at the show floor. | S16: Medium | T16: High | U16: Third party: 650+ exhibitors; 130,000 to 150,000 visitors (est.) | V16: Not published. | W16: Exhibitor sales for 2026 probably closed. Confirm with the organiser. | X16: Attend as a visitor. Walk the ultrasound and imaging aisles and collect importer cards. Nearest event on this list. | Y16: https://expo.taiwan-healthcare.org/en/
A17: 2 | B17: P2 | C17: Diagnostics | D17: Taiwan | E17: TSOC Winter Scientific Meeting 2026 (Taiwan Society of Cardiology) | F17: 46368 | G17: 46369 | H17: 46357 | I17: 12 to 13 Dec 2026 | J17: Confirmed | K17: Confirmed | L17: Taipei International Convention Center (TICC), Taipei | M17: Society scientific meeting | N17: Cardiology and echo | O17: Cardiology KOL access in Taipei. | P17: Expected, not verified: GE HealthCare, Philips, Canon expected. | Q17: Unverified. | R17: Rotary Trading (Canon Medical agent) is a known ultrasound dealer. Other Taiwan importers to scout at the show floor. | S17: High | T17: Low | U17: Not published | V17: Not published. Request the exhibitor guide from the organiser. | W17: Not published. Event is 7 weeks away. | X17: Optional. Attend only if combined with Healthcare+ Expo trip. | Y17: https://tsocmeeting.org/
A18: 3 | B18: P1 | C18: Diagnostics | D18: Taiwan | E18: ASCI 2027 and TRC 2027 (Radiological Society of the ROC annual meeting) | F18: 46464 | G18: 46467 | H18: 46447 | I18: 18 to 21 Mar 2027 | J18: Provisional | K18: Reported in the RSROC annual schedule (read through a search extract, site blocked my fetch). Verify | L18: NTUH International Convention Center, Taipei | M18: National congress with Asian cardiovascular imaging society | N18: Radiology, cardiovascular imaging | O18: Taiwan's top radiology meeting. TRC 2026 was at Kaohsiung Exhibition Center in April. | P18: Expected, not verified: GE HealthCare, Philips, Canon Medical (agent: Rotary Trading), Alpinion, Samsung Medison, Siemens Healthineers. Mindray and SonoScape: no Taiwan exhibitor evidence found. | Q18: Unverified. | R18: Rotary Trading (Canon Medical agent) is a known ultrasound dealer. Other Taiwan importers to scout at the show floor. | S18: High | T18: Medium | U18: Not published | V18: Not published. Request the exhibitor guide from the organiser. | W18: Not published. Ask RSROC secretariat (02 25865331). | X18: Request the exhibitor guide. KOL meetings with radiologists. | Y18: https://www.rsroc.org.tw/news/news_detail.asp?news_id=96
A19: 4 | B19: P2 | C19: Diagnostics | D19: Taiwan | E19: TAOG 66th Annual Congress 2027 (Taiwan Association of Obstetrics and Gynecology) | H19: 46447 | I19: Late Mar 2027 (not published) | J19: TBC | K19: TBC. Annual pattern: late March (65th was 28 to 29 Mar 2026 at TICC) | L19: Taipei International Convention Center (TICC) expected | M19: Society congress | N19: OB/GYN ultrasound | O19: OB/GYN ultrasound buyers. TAOG publishes a vendor exhibition registration form each year, so there is a documented booth path. | P19: Expected, not verified: GE HealthCare, Samsung Medison, Philips, Alpinion expected. | Q19: Unverified. | R19: Rotary Trading (Canon Medical agent) is a known ultrasound dealer. Other Taiwan importers to scout at the show floor. | S19: High | T19: High | U19: Not published | V19: Not published (registration form exists). | W19: 2024 exhibitor registration form was published; the 2027 form should appear around late 2026. | X19: Watch taog.org.tw and email the secretariat in November. | Y19: https://www.taog.org.tw/year_list.php
A20: 5 | B20: P2 | C20: Diagnostics | D20: Taiwan | E20: Taiwan Association of Radiological Technologists 60th Annual Meeting 2027 | H20: 46447 | I20: March 2027 (not published) | J20: TBC | K20: TBC. Annual pattern: March (59th was March 2026 at Kaohsiung Exhibition Center) | L20: Rotating city | M20: Society annual meeting | N20: Radiographers and sonographers | O20: Daily users who influence purchases. | P20: Expected, not verified: GE HealthCare, Philips, Canon Medical (agent: Rotary Trading), Alpinion, Samsung Medison, Siemens Healthineers. Mindray and SonoScape: no Taiwan exhibitor evidence found. | Q20: Unverified. | R20: Rotary Trading (Canon Medical agent) is a known ultrasound dealer. Other Taiwan importers to scout at the show floor. | S20: Medium | T20: Medium | U20: Not published | V20: Not published. Request the exhibitor guide from the organiser. | W20: Not published. | X20: Search for the official notice in January. | Y20: https://www.rsroc.org.tw/
A21: 6 | B21: P2 | C21: Diagnostics | D21: Taiwan | E21: TSOC Annual Meeting 2027 (Taiwan Society of Cardiology) | H21: 46508 | I21: May 2027 (not published) | J21: TBC | K21: TBC. Annual pattern: May (2026 was 15 to 17 May at TICC and WTC Hall 1A) | L21: Taipei (TICC expected) | M21: Society annual meeting | N21: Cardiology and echo | O21: Largest Taiwan cardiology meeting. | P21: Expected, not verified: GE HealthCare, Philips, Canon expected. | Q21: Unverified. | R21: Rotary Trading (Canon Medical agent) is a known ultrasound dealer. Other Taiwan importers to scout at the show floor. | S21: High | T21: Low | U21: Large | V21: Not published. Request the exhibitor guide from the organiser. | W21: Not published. | X21: Optional. Check tsoc.org.tw in early 2027. | Y21: https://www.tsoc.org.tw/
A22: 7 | B22: P2 | C22: Diagnostics | D22: Taiwan | E22: Taiwan Society of Emergency Medicine Annual Meeting 2027 | H22: 46539 | I22: June 2027 (not published) | J22: TBC | K22: TBC. Annual pattern: June (2026 was 26 to 27 Jun at NTUH) | L22: Taipei (NTUH expected) | M22: Society annual meeting | N22: Emergency medicine, POCUS | O22: Handheld and portable ultrasound buyers. | P22: Expected, not verified: GE HealthCare (Vscan), Philips (Lumify), Butterfly expected. | Q22: Unverified. | R22: Rotary Trading (Canon Medical agent) is a known ultrasound dealer. Other Taiwan importers to scout at the show floor. | S22: Medium | T22: Medium | U22: Not published | V22: Not published. Request the exhibitor guide from the organiser. | W22: Not published. | X22: Check sem.org.tw in spring 2027. | Y22: https://www.sem.org.tw/News/12/Index
A23: 8 | B23: P2 | C23: Both | D23: Taiwan | E23: Medical Taiwan 2027 | F23: 46576 | G23: 46578 | H23: 46569 | I23: 8 to 10 Jul 2027 | J23: Confirmed | K23: Confirmed per organiser page | L23: Taipei Nangang Exhibition Center Hall 1, Taipei | M23: International trade exhibition | N23: Smart medical, elderly care, innovative devices | O23: Second Taiwan show a year, focused on devices and exports. Good for importers and OEM contacts. | P23: Not documented. | Q23: Unverified. | R23: Rotary Trading (Canon Medical agent) is a known ultrasound dealer. Other Taiwan importers to scout at the show floor. | S23: Low | T23: High | U23: Not published | V23: Not published. | W23: Booth sales likely open. Ask the organiser. | X23: Visit or exhibit with a local importer. Compare cost with Healthcare+ Expo. | Y23: https://www.medicaltaiwan.com.tw/zh-tw/index.html
A24: 9 | B24: P2 | C24: Diagnostics | D24: Taiwan | E24: Taipei International Breast Cancer Symposium 2027 (Taiwan Breast Cancer Society) | H24: 46631 | I24: Sep to Oct 2027 (not published) | J24: TBC | K24: TBC. Annual or two yearly pattern: 2026 is 19 to 20 Sep, 2024 was 26 to 27 Oct | L24: Taipei Nangang Exhibition Center Hall 2 (7F) in 2024 and 2026 | M24: International symposium | N24: Breast imaging, ABUS | O24: Breast imaging KOLs. SUMROC activity pages list the 2024 edition. | P24: Unverified. | Q24: Unverified. | R24: Rotary Trading (Canon Medical agent) is a known ultrasound dealer. Other Taiwan importers to scout at the show floor. | S24: High | T24: Low | U24: Not published | V24: Not published. Request the exhibitor guide from the organiser. | W24: Not published. | X24: Check bcst.org.tw in mid 2027. | Y24: https://www.tpta.org.tw/articles.php?type=forwarded&pid=520
A25: 10 | B25: P2 | C25: Diagnostics | D25: Taiwan | E25: TSA 71st Annual Meeting 2027 (Taiwan Society of Anesthesiologists) | H25: 46631 | I25: Sep 2027 (not published) | J25: TBC | K25: TBC. Annual pattern: late September (70th is 26 to 27 Sep 2026 at NTUH) | L25: Taipei (NTUH International Convention Center in 2026) | M25: Society annual meeting | N25: Anaesthesia, regional block ultrasound | O25: Nerve block ultrasound users. Handheld and portable fit. | P25: Expected, not verified: Fujifilm Sonosite, GE HealthCare expected. | Q25: Unverified. | R25: Rotary Trading (Canon Medical agent) is a known ultrasound dealer. Other Taiwan importers to scout at the show floor. | S25: Medium | T25: Medium | U25: Not published | V25: Not published. Request the exhibitor guide from the organiser. | W25: Not published. | X25: Check anesth.org.tw in 2027. | Y25: https://www.anesth.org.tw/events/content.asp?ID=3091&EduType=1
A26: 11 | B26: P1 | C26: Diagnostics | D26: Taiwan | E26: SUMROC Annual Meeting and 9th Asia Pacific Forum 2027 (Society of Ultrasound in Medicine, ROC) | H26: 46661 | I26: Oct to Nov 2027 (not published) | J26: TBC | K26: TBC. Annual pattern: mid to late October (2026 is 31 Oct to 1 Nov, TICC) | L26: Taipei International Convention Center or NTU College of Medicine | M26: Society annual meeting | N26: All clinical ultrasound | O26: Taiwan's ultrasound society. The 2026 page shows GE HealthCare Ultrasound, Alpinion and Rotary Trading (Canon agent) as supporters. KOL access is the main prize. | P26: Confirmed on the 2026 page: GE HealthCare Ultrasound, Alpinion, Rotary Trading (Canon Medical agent). | Q26: Confirmed for GE, Alpinion, Canon agent (2026 page logos). | R26: Rotary Trading (Canon Medical agent) is a known ultrasound dealer. Other Taiwan importers to scout at the show floor. | S26: High | T26: Medium | U26: Not published. Past venues: TICC and NTU basic medical building | V26: Not published. Request the exhibitor guide from the organiser. | W26: Sponsor terms not published. The 2026 meeting is 31 Oct, so ask for the 2027 terms right after it. | X26: Attend SUMROC 2026 on 31 Oct if possible to meet the board. Otherwise email sumroc@sumroc.org.tw. | Y26: https://www.sumroc.org.tw/index.php?action=annual
A27: 12 | B27: P2 | C27: Both | D27: Taiwan | E27: Healthcare+ Expo Taiwan 2027 | H27: 46722 | I27: Early Dec 2027 (not published) | J27: TBC | K27: TBC. Annual pattern: first week of December (2026 is 3 to 6 Dec, 2025 was 4 to 7 Dec) | L27: Taipei Nangang Exhibition Center Hall 1, Taipei | M27: Trade exhibition | N27: Medical devices, smart hospital | O27: Same show as Dec 2026. Plan to exhibit with an importer after seeing the 2026 floor. | P27: Expected, not verified: Same as 2026. See the Dec 2026 row. | Q27: Unverified. | R27: Rotary Trading (Canon Medical agent) is a known ultrasound dealer. Other Taiwan importers to scout at the show floor. | S27: Medium | T27: High | U27: See 2026 row | V27: Not published. | W27: Booth sales typically open 6 to 9 months ahead. | X27: Decide after the Dec 2026 visit. Ask the organiser for the 2027 booth price. | Y27: https://expo.taiwan-healthcare.org/en/
A28: 1 | B28: P2 | C28: Diagnostics | D28: South Korea | E28: KSE 2026, 61st Korean Society of Echocardiography Autumn Meeting | F28: 46361 | G28: 46362 | H28: 46357 | I28: 5 to 6 Dec 2026 | J28: Confirmed | K28: Confirmed | L28: Grand Walkerhill Seoul, Seoul | M28: Society scientific meeting | N28: Echocardiography | O28: Cardiac echo KOLs and sonographers. Also the Yeongnam echo winter workshop on 12 Dec 2026 at Keimyung University, Daegu. | P28: Expected, not verified: Samsung Medison, GE HealthCare, Philips, Canon expected. | Q28: Likely. Not verified for this edition. | R28: Korean importers and regional dealers. Note that Samsung Medison and Alpinion sell direct, so dealer recruitment should focus on Chinese OEM friendly importers. | S28: High | T28: Low | U28: About 1,000 (est.) | V28: Not published. Request the exhibitor guide from the organiser. | W28: Event is 6 weeks away. Ask the society office now. | X28: Ask for visitor access. Note names of the hands on session faculty. | Y28: https://www.ksecho.org/academic_event/annual_schedule_all.php
A29: 2 | B29: P2 | C29: Diagnostics | D29: South Korea | E29: ISCU 2026 and 29th Regular Meeting of the Korean Association of Clinical Ultrasound, with Hands On School | F29: 46361 | G29: 46362 | H29: 46357 | I29: 5 to 6 Dec 2026 | J29: Confirmed | K29: Confirmed | L29: COEX Magok, Seoul | M29: International symposium and hands on school | N29: Clinical and point of care ultrasound | O29: Clinical ultrasound used by non radiologists (family medicine, internal medicine, orthopaedics). A hands on school normally needs scanners from vendors, a cheap route to get probes in doctors' hands. Suits SonoEye, SonoAir and SonoBook. | P29: Expected, not verified: Samsung Medison likely. Others unverified. | Q29: Unverified. Sponsor page not retrieved. | R29: Korean importers and regional dealers. Note that Samsung Medison and Alpinion sell direct, so dealer recruitment should focus on Chinese OEM friendly importers. | S29: High | T29: Medium | U29: Not published | V29: Not published. Request the exhibitor guide from the organiser. | W29: Abstract deadline 30 Oct 2026 (not relevant for vendors). Sponsor terms not found, event is 6 weeks away. | X29: Contact KACU this week to ask about equipment loan for the hands on school. | Y29: https://iscu.or.kr/
A30: 3 | B30: P1 | C30: Both | D30: South Korea | E30: KIMES 2027, 42nd Korea International Medical and Hospital Equipment Show | F30: 46464 | G30: 46467 | H30: 46447 | I30: 18 to 21 Mar 2027 | J30: Provisional | K30: Reported on the official site listing (read through a search extract, my direct fetch of kimes.kr returned no text). Third party listings agree. Re check on kimes.kr when booth sales open | L30: COEX Halls, Gangnam, Seoul (about 45,000 sqm) | M30: Trade exhibition | N30: Medical devices, ultrasound, radiology, hospital equipment | O30: Korea's #1 medtech show and the main dealer scouting floor. Importers and regional dealers walk it. Samsung Medison and GE HealthCare use it as a launch stage. | P30: Confirmed at KIMES 2026: Samsung Medison (One Platform, V4, EVO Q10) and GE HealthCare (booth C200, ultrasound and fatty liver quantification). Mindray, SonoScape, Philips: not found. | Q30: Confirmed for Samsung and GE (2026 press releases). | R30: Korean importers and regional dealers. Note that Samsung Medison and Alpinion sell direct, so dealer recruitment should focus on Chinese OEM friendly importers. | S30: Medium | T30: High | U30: KIMES 2026: about 1,500 booths (media). Organiser Korea E and Ex | V30: Not published. | W30: Booth application dates not found. KIMES opens exhibitor recruitment roughly 6 to 9 months ahead, so ask the organiser now. | X30: Priority 1 for distributor recruitment. Ask Korea E and Ex for the 2027 booth form and early bird rate. | Y30: https://www.kimes.kr/
A31: 4 | B31: P3 | C31: Diagnostics | D31: South Korea | E31: KSC Spring Conference 2027 (Korean Society of Cardiology) | H31: 46478 | I31: April 2027 (not published) | J31: TBC | K31: TBC. Annual pattern: April (2026 was 17 to 18 Apr, Gyeongju, with ACC Asia) | L31: Rotating city | M31: Society conference | N31: Cardiology | O31: Cardiology KOL access. Secondary to the autumn meeting. | P31: Expected, not verified: GE HealthCare, Philips, Samsung Medison expected. | Q31: Unverified. | R31: Korean importers and regional dealers. Note that Samsung Medison and Alpinion sell direct, so dealer recruitment should focus on Chinese OEM friendly importers. | S31: Medium | T31: Low | U31: Not published | V31: Not published. Request the exhibitor guide from the organiser. | W31: Not published. | X31: Check circulation.or.kr in January. | Y31: https://www.circulation.or.kr/bbs/?code=meeting
A32: 5 | B32: P2 | C32: Diagnostics | D32: South Korea | E32: KSEM 2027 Spring Conference (Korean Society of Emergency Medicine) | H32: 46478 | I32: Apr to Jun 2027 (not published) | J32: TBC | K32: TBC. No pattern: 2025 was 17 to 18 Apr (Gwangju), 2024 was 27 to 28 Jun (Daegu) | L32: Rotating city | M32: Society conference | N32: Emergency medicine, POCUS | O32: Emergency physicians buy handheld and portable ultrasound (SonoEye, SonoBook). | P32: Expected, not verified: Samsung Medison, GE HealthCare (Vscan) likely. | Q32: Unverified. | R32: Korean importers and regional dealers. Note that Samsung Medison and Alpinion sell direct, so dealer recruitment should focus on Chinese OEM friendly importers. | S32: Medium | T32: Medium | U32: Not published | V32: Not published. Request the exhibitor guide from the organiser. | W32: Not published. Society was recruiting an event agency in 2026. | X32: Check emergency.or.kr in January. | Y32: https://emergency.or.kr/
A33: 6 | B33: P3 | C33: Diagnostics | D33: South Korea | E33: GBCC 2027, Global Breast Cancer Conference (Korean Breast Cancer Society) | H33: 46478 | I33: Spring 2027 (not published) | J33: TBC | K33: TBC. 2026 edition held at Grand Walkerhill Seoul (press), month not confirmed | L33: Seoul (expected) | M33: International conference | N33: Breast cancer, breast imaging | O33: Breast surgeons and radiologists. Smaller exhibition. | P33: Unverified. | Q33: Unverified. | R33: Korean importers and regional dealers. Note that Samsung Medison and Alpinion sell direct, so dealer recruitment should focus on Chinese OEM friendly importers. | S33: Medium | T33: Low | U33: Not published | V33: Not published. Request the exhibitor guide from the organiser. | W33: Not published. | X33: Optional. Check kbcs.or.kr in January. | Y33: https://www.kbcs.or.kr/html/
A34: 7 | B34: P1 | C34: Diagnostics | D34: South Korea | E34: KSUM 2027, 58th Annual Congress of the Korean Society of Ultrasound in Medicine | H34: 46508 | I34: May 2027 (not published) | J34: TBC | K34: TBC. Annual pattern: early May (2026 was 7 to 8 May at COEX) | L34: COEX, Seoul (venue used in 2025 and 2026) | M34: National society congress | N34: All clinical ultrasound | O34: Korea's top ultrasound KOL meeting. English language, international delegates. The right place for CHISON publicity. | P34: Confirmed at KSUM 2026: Canon Medical Korea ran a luncheon symposium. Sponsors listed on 10times include Philips, GE HealthCare and Canon (unofficial listing). Samsung Medison, Mindray, SonoScape not found. | Q34: Confirmed for Canon. Philips and GE from an unofficial listing. | R34: Korean importers and regional dealers. Note that Samsung Medison and Alpinion sell direct, so dealer recruitment should focus on Chinese OEM friendly importers. | S34: High | T34: Medium | U34: KSUM 2026: about 1,000 attendees from 30 countries (press) | V34: Not published. Request the exhibitor guide from the organiser. | W34: Sponsor terms not published. The 2026 edition had abstract deadline on 23 Feb. Expect sponsor call from January. | X34: Email the KSUM office in January for the sponsorship tier list and luncheon symposium slots. | Y34: https://2026.ksum.or.kr/about/about.php
A35: 8 | B35: P2 | C35: Diagnostics | D35: South Korea | E35: KHF 2027, K Hospital and Healthtech Fair (Korean Hospital Association) | H35: 46600 | I35: August 2027 (not published) | J35: TBC | K35: TBC. Annual pattern: August (2026 was 19 to 21 Aug at COEX) | L35: COEX Halls C and D, Seoul | M35: Hospital trade fair | N35: Hospital equipment and health tech | O35: Hospital purchasing managers and hospital owners. Runs by the Korean Hospital Association with Messe eSang. | P35: Not documented. | Q35: Unverified. | R35: Korean importers and regional dealers. Note that Samsung Medison and Alpinion sell direct, so dealer recruitment should focus on Chinese OEM friendly importers. | S35: Low | T35: High | U35: Not published | V35: Not published. | W35: Not published. | X35: Visit as buyer in 2027 if KIMES dealer meetings are productive. | Y35: https://khospital.org/
A36: 9 | B36: P1 | C36: Diagnostics | D36: South Korea | E36: KCR 2027, 83rd Korean Congress of Radiology | F36: 46652 | G36: 46655 | H36: 46631 | I36: 22 to 25 Sep 2027 | J36: Confirmed | K36: Dates confirmed on radiology.or.kr. Venue reported as COEX Magok (page text garbled, verify) | L36: COEX Magok, Seoul (reported) | M36: National congress | N36: Radiology | O36: Radiology KOL meeting with a large exhibition. KCR 2026 moved to KINTEX for the first time in 20 years. | P36: Confirmed at KCR 2026: GE HealthCare luncheon symposium. Samsung Medison, Philips, Canon expected. | Q36: Confirmed for GE (2026). Others likely. | R36: Korean importers and regional dealers. Note that Samsung Medison and Alpinion sell direct, so dealer recruitment should focus on Chinese OEM friendly importers. | S36: High | T36: Medium | U36: KCR 2026: 2,135 abstracts submitted (press) | V36: Not published. Request the exhibitor guide from the organiser. | W36: Exhibitor call normally opens in spring. | X36: Ask KCR secretariat in March 2027 for the exhibitor guide. | Y36: https://www.radiology.or.kr/
